Workbook
Name INFRA: FRE!$O$189
Name MCMV: FRE!$A$12
Name módulo: FRE!$F$32
Name programa: FRE!$E$4

Sheet Instruções
B2: FRE
B4: O Programa deverá ser o primeiro item do formulário a ser preenchido, haja vista que a estrutura do formulário pode ser alterada de acordo com o programa.
B5: O formulário é auto-explicativo com comentários em algumas células, que detalham sua forma de preenchimento.
B6: Caso necessário podem ser inseridas linhas nas tabelas de tipologias, com o cuidado de manter a formatação e as formulas.
B8: Planilhas Orçamentárias
B10: Para apresentação dos custos de habitação devem ser preenchidas as planilhas Orç_analítio_Hab, sendo permitido em alguns programas inserção da infra-estrutura juntamente com a habitação.
B11: O preenchimento da planilha Orç_sintético_Hab será automático e representa o orçamento sintético da habitação (com ou sem infra inclusa).
B12: O Orç_sintético_Hab poderá ser preenchido diretamente (sem necessidade de preencher a planilha Orç_analítico_Hab), sendo obrigatório nesses casos o preenchimento manual dos itens referentes ao "Custo direto", "BDI" e "Custo global" na linha 99 da aba "FRE".
B13: Caso a infra seja orçada em separado deve ser preenchido o Orç_eventos_Infra, onde é permitida a inserção de linhas desde que mantida a estrutura analítica do orçamento, com o cuidado de manter a formatação e formulas de soma.
B14: No Caso do financiamento à produção de lotes urbanizados - PRODULOTE - deve ser preenchido apenas o Orç_eventos_Infra.
B15: O preenchimento da planilha Orç_analítico_Equipamento_Faixa_I é necessário apenas no produtos MCMV (FAR ou FDS).
B16: Para os demais programas caso haja equipamentos condominiais estes deve ser incluídos no orçamento da habitação ou infra.
... B31: A coluna "Infra não incidente" é uma previsão da construtora para as infraestruturas necessárias para a entrega do empreendimento, mas que seus custos não são incidentes no contrato. É um cronograma informativo para registrar quando estas obras serão realizadas.

Sheet FRE
A1: (escolha) | N1: Grau de sigilo
A2: Apoio à Produção de Imóveis - Pessoa Jurídica | F2: FRE - Ficha Resumo do Empreendimento - Habitação | N2: #EXTERNO.CONFIDENCIAL
A3: PEC / MGE
A4: PEC / MPE | D4: Programa: | E4: Apoio à Produção de Imóveis - Pessoa Jurídica
A5: Alocação de Recursos em Construção
A6: Produção de Lotes Urbanizados - PRODULOTE - PJ | B6: Nome do Empreendimento
A7: PCVA - Recursos FAR | B7: {NOME DO EMPRRENDIMENTO}
A8: PCVA Entidades - Recursos FDS
A9: Outro | B9: Endereço do Empreendimento (conforme Matrícula) | M9: Complemento
B10: {RUA} | M10: {COMPLEMENTO}
B12: Bairro | I12: Município | M12: UF | N12: CEP
B13: {SETOR} | I13: {CIDADE} | M13: GO | N13: {CEP}
B15: Proponente | M15: CNPJ/CPF
B16: {PROPONENTE} | M16: {DOC. PROPONENTE}
B18: Construtora | M18: CNPJ/CPF
B19: {CONSTRUTORA} | M19: {DOC. CONSTRUTORA}
B21: Responsável técnico | J21: CAU/CREA | M21: CPF/CNPJ
B22: {RESPONSÁVEL TÉCNICO} | J22: {CREA} | M22: {DOC. RESPONSÁVEL}
B24: Incorporador (conforme Memorial de Incorporação ou RI) | M24: CPF/CNPJ
B25: {INCORPORADOR} | M25: {DOC. INCORPORADOR}
B27: Nome para contato | J27: Telefone | M27: E-mail
B28: {RESPONSÁVEL TÉCNICO} | J28: {TEL. CONTATO} | M28: {EMAIL}
E30: Este laudo refere-se a um módulo? | F30: não | I30: Número do módulo:
E34: Tipo do empreendimento: | F34: condomínio
D36: Casas | E36: {Nº DE UNIDADES} | F36: unidades | I36: Unidades comerciais | K36: unidades | M36: Tipos de UH diferentes
D38: Apartamentos | F38: unidades | I38: UHs não financiáveis | K38: unidades | M38: Nº de blocos de apartamentos
B40: Descrição do empreendimento (tipologias, blocos, equipamentos de uso comum, lazer e infraestrutura):
A41: (escolha) | B41: CONDOMÍNIO HORIZONTAL COMPOSTO POR {Nº UNIDADES} UNIDADES TÉRREAS COM MESMA TIPOLOGIA, CONTENDO CADA UMA, 3 QUARTOS SENDO UM SUITE, BANHEIRO SOCIAL, BANHEIRO PRIVATIVO, SALA DE ESTAR, COZINHA, ÁREA DE SERVIÇO E GARAGEM DESCOBERTA, CONTARÁ COM PORTARIA (GUARITA/ADIMINISTRAÇÃO)(PREENCHER COM INFORMAÇÕES DO CONDOMÍNIO). UTILIZAÇÃO DE SISTEMA DE FOSSA SÉPTICA E SUMIDOURO PARA TRATAMENTO DE ESGOTO.
A42: =IF($F$47="convencional","Estrutura + vedação",IF($F$47="não convencional","Paredes de concreto moldado in loco NBR 16055",IF($F$47="inovador","Pré-moldado bloco cerâmico",""))) -> Estrutura + vedação
A43: =IF($F$47="convencional","Alvenaria estrutural",IF($F$47="inovador","Concreto leve","")) -> Alvenaria estrutural
A44: =IF($F$47="não convencional","Painéis pré-moldados de concreto alveolar NBR 16475","")
A45: =IF($F$47="não convencional","Painéis pré-moldados de concreto NBR 16475","") | E45: Padrão de acabamento: | F45: normal
A46: =IF($F$47="inovador","PVC + concreto","")
A47: =IF($F$47="inovador","Wood frame","") | E47: Processo construtivo: | F47: convencional | J47: Sistema Construtivo: | K47: Estrutura + vedação
A48: =IF($F$47="inovador","Painéis compósitos","")
A49: =IF($F$47="inovador","Bloco gesso","") | B49: GPS: | D49: Datum: | E49: SAD-69 | F49: (preferencial: SAD-69) | J49: Longitude (oeste): | K49: 49°08'4.0" | M49: Latitude: | N49: 16°40'29.2" | O49: sul
A50: =IF($F$47="inovador","Solo-cimento","")
A51: =IF($F$47="inovador","outro (especificar)","") | D51: Área total do terreno | E51: =I66 -> {ÁREA DO LOTE} | F51: =IF($O$53=0,0,E51/$E$51) -> #VALUE! | J51: Área do sistema viário | K51: 0 | L51: =IF($O$53=0,0,K51/$E$51) -> #VALUE! | N51: Área líquida do terreno
Q52: Área total equivalente do empreendimento (total da col. 38):
D53: Área de APP | E53: 0 | F53: =IF($O$53=0,0,E53/$E$51) -> #VALUE! | J53: Área de praças/áreas verdes | K53: 0 | L53: =IF($O$53=0,0,K53/$E$51) -> #VALUE! | N53: =E51-SUM(E53,E55,K51,K53,K55) -> #VALUE! | O53: =IF($N$53=0,0,N53/$E$51) -> #VALUE!
...

Sheet Orç_sintético_Hab
A1: (escolha) | E1: Orçamento Sintético - Habitação | K1: Grau de sigilo
A2: Habitacional horizontal | G2: =FRE!$D$4 -> Programa: | H2: =FRE!$E$4 -> Apoio à Produção de Imóveis - Pessoa Jurídica | K2: #EXTERNO.CONFIDENCIAL
A3: Vertical: habit. / salas / misto
A4: Vertical andar livre
A5: Vertical parede de concreto
T20: =A2 -> Habitacional horizontal | X20: =A3 -> Vertical: habit. / salas / misto | AB20: =A4 -> Vertical andar livre | AF20: =A5 -> Vertical parede de concreto
T21: mínimo | U21: máximo infra sintética | V21: máximo infra analítica | X21: mínimo | Y21: máximo infra sintética | Z21: máximo infra analítica | AB21: mínimo | AC21: máximo infra sintética | AD21: máximo infra analítica | AF21: mínimo | AG21: máximo infra sintética | AH21: máximo infra analítica
B22: Tipologia: | C22: Habitacional horizontal | I22: =IF(FRE!$A$12=1,"sim",FRE!N189) -> não
B24: Item | C24: Serviço | K24: Incidência | L24: Custo | M24: % acumulado | O24: =IF(C22="(escolha)","(escolha a tipologia)",C22) -> Habitacional horizontal | R24: Status | AI24: incidencia calculada | AJ24: erro acumulado | AK24: Calculo Arredondamento Monetário
B25: 1 | C25: SERVIÇOS PRELIMINARES GERAIS | K25: =SUM(K26:K35) -> 0.16 | L25: =SUM(L26:L35) -> 0 | M25: =IF(SUM($L$25,$L$36,$L$39,$L$40,$L$45,$L$48,$L$55,$L$62,$L$71,$L$75)=0,0,L25/SUM($L$25,$L$36,$L$39,$L$40,$L$45,$L$48,$L$55,$L$62,$L$71,$L$75)) -> 0 | AK25: =SUM(AK26:AK35) -> 0
B26: 1.1 | C26: serviços técnicos (projetos, orçamentos, levant. topog., sondagem, licenças e PCMAT) | K26: 0.0076 | L26: =ROUND(K26*FRE!$M$187,2) -> 0 | O26: =IF($O$24=$T$20,T26,IF($O$24=$X$20,X26,IF($O$24=$AB$20,AB26,AF26))) -> 0.005 | P26: a | Q26: =IF(OR(FRE!$N$189="não",FRE!$N$189<"0"), IF($O$24=$T$20,U26,IF($O$24=$X$20,Y26,IF($O$24=$AB$20,AC26,AG26))), IF($O$24=$T$20,V26,IF($O$24=$X$20,Z26,IF($O$24=$AB$20,AD26,AH26)))) -> 0.0076 | R26: =IF(K26>Q26,"Excedeu limites",IF(K26<O26,"Abaixo do limite","ok")) -> ok | T26: 0.005 | U26: 0.0076 | V26: 0.0076 | X26: 0.005 | Y26: 0.0076 | Z26: 0.0076 | AB26: 0.005 | AC26: 0.0076 | AD26: 0.0076 | AF26: 0.005 | AG26: 0.0076 | AH26: 0.0076 | AI26: =Orç_analítico_Hab!M19/IF(Orç_analítico_Hab!M$430=0,1,Orç_analítico_Hab!M$430) -> 0 | AJ26: =AI26-ROUND(AI26,4) -> 0 | AK26: =ROUND(L26,2) -> 0
B27: 1.2 | C27: instalações e canteiros (barracão, cercamento e placa da obra) | K27: 0.019 | L27: =ROUND(K27*FRE!$M$187,2) -> 0 | O27: =IF($O$24=$T$20,T27,IF($O$24=$X$20,X27,IF($O$24=$AB$20,AB27,AF27))) -> 0.001 | P27: a | Q27: =IF(OR(FRE!$N$189="não",FRE!$N$189<"0"), IF($O$24=$T$20,U27,IF($O$24=$X$20,Y27,IF($O$24=$AB$20,AC27,AG27))), IF($O$24=$T$20,V27,IF($O$24=$X$20,Z27,IF($O$24=$AB$20,AD27,AH27)))) -> 0.019 | R27: =IF(K27>Q27,"Excedeu limites",IF(K27<O27,"Abaixo do limite","ok")) -> ok | T27: 0.001 | U27: 0.019 | V27: 0.019 | X27: 0.001 | Y27: 0.019 | Z27: 0.019 | AB27: 0.001 | AC27: 0.019 | AD27: 0.019 | AF27: 0.001 | AG27: 0.019 | AH27: 0.019 | AI27: =Orç_analítico_Hab!M20/IF(Orç_analítico_Hab!M$430=0,1,Orç_analítico_Hab!M$430) -> 0 | AJ27: =AI27-ROUND(AI27,4)+AJ26 -> 0 | AK27: =ROUND(L27,2) -> 0
B28: 1.3 | C28: ligações provisórias (água, energia, telefone e esgoto) | K28: 0.0004 | L28: =ROUND(K28*FRE!$M$187,2) -> 0 | O28: =IF($O$24=$T$20,T28,IF($O$24=$X$20,X28,IF($O$24=$AB$20,AB28,AF28))) -> 0.0001 | P28: a | Q28: =IF(OR(FRE!$N$189="não",FRE!$N$189<"0"), IF($O$24=$T$20,U28,IF($O$24=$X$20,Y28,IF($O$24=$AB$20,AC28,AG28))), IF($O$24=$T$20,V28,IF($O$24=$X$20,Z28,IF($O$24=$AB$20,AD28,AH28)))) -> 0.0004 | R28: =IF(K28>Q28,"Excedeu limites",IF(K28<O28,"Abaixo do limite","ok")) -> ok | T28: 0.0001 | U28: 0.0004 | V28: 0.0004 | X28: 0.0001 | Y28: 0.0004 | Z28: 0.0004 | AB28: 0.0001 | AC28: 0.0004 | AD28: 0.0004 | AF28: 0.0001 | AG28: 0.0004 | AH28: 0.0004 | AI28: =Orç_analítico_Hab!M21/IF(Orç_analítico_Hab!M$430=0,1,Orç_analítico_Hab!M$430) -> 0 | AJ28: =AI28-ROUND(AI28,4)+AJ27 -> 0 | AK28: =ROUND(L28,2) -> 0
B29: 1.4 | C29: manutenção canteiro/consumo | K29: 0.0143 | L29: =ROUND(K29*FRE!$M$187,2) -> 0 | O29: =IF($O$24=$T$20,T29,IF($O$24=$X$20,X29,IF($O$24=$AB$20,AB29,AF29))) -> 0.01 | P29: a | Q29: =IF(OR(FRE!$N$189="não",FRE!$N$189<"0"), IF($O$24=$T$20,U29,IF($O$24=$X$20,Y29,IF($O$24=$AB$20,AC29,AG29))), IF($O$24=$T$20,V29,IF($O$24=$X$20,Z29,IF($O$24=$AB$20,AD29,AH29)))) -> 0.0143 | R29: =IF(K29>Q29,"Excedeu limites",IF(K29<O29,"Abaixo do limite","ok")) -> ok | T29: 0.01 | U29: 0.0143 | V29: 0.0143 | X29: 0.01 | Y29: 0.0143 | Z29: 0.0143 | AB29: 0.01 | AC29: 0.0143 | AD29: 0.0143 | AF29: 0.01 | AG29: 0.0143 | AH29: 0.0143 | AI29: =Orç_analítico_Hab!M22/IF(Orç_analítico_Hab!M$430=0,1,Orç_analítico_Hab!M$430) -> 0 | AJ29: =AI29-ROUND(AI29,4)+AJ28 -> 0 | AK29: =ROUND(L29,2) -> 0
B30: 1.5 | C30: transportes máquinas e equipamentos | K30: 0.0394 | L30: =ROUND(K30*FRE!$M$187,2) -> 0 | O30: =IF($O$24=$T$20,T30,IF($O$24=$X$20,X30,IF($O$24=$AB$20,AB30,AF30))) -> 0.006 | P30: a | Q30: =IF(OR(FRE!$N$189="não",FRE!$N$189<"0"), IF($O$24=$T$20,U30,IF($O$24=$X$20,Y30,IF($O$24=$AB$20,AC30,AG30))), IF($O$24=$T$20,V30,IF($O$24=$X$20,Z30,IF($O$24=$AB$20,AD30,AH30)))) -> 0.0394 | R30: =IF(K30>Q30,"Excedeu limites",IF(K30<O30,"Abaixo do limite","ok")) -> ok | T30: 0.006 | U30: 0.0394 | V30: 0.0394 | X30: 0.006 | Y30: 0.0394 | Z30: 0.0394 | AB30: 0.006 | AC30: 0.0394 | AD30: 0.0394 | AF30: 0.006 | AG30: 0.0394 | AH30: 0.0394 | AI30: =Orç_analítico_Hab!M23/IF(Orç_analítico_Hab!M$430=0,1,Orç_analítico_Hab!M$430) -> 0 | AJ30: =AI30-ROUND(AI30,4)+AJ29 -> 0 | AK30: =ROUND(L30,2) -> 0
B31: 1.6 | C31: controle tecnológico | K31: 0.0067 | L31: =ROUND(K31*FRE!$M$187,2) -> 0 | O31: =IF($O$24=$T$20,T31,IF($O$24=$X$20,X31,IF($O$24=$AB$20,AB31,AF31))) -> 0.0005 | P31: a | Q31: =IF(OR(FRE!$N$189="não",FRE!$N$189<"0"), IF($O$24=$T$20,U31,IF($O$24=$X$20,Y31,IF($O$24=$AB$20,AC31,AG31))), IF($O$24=$T$20,V31,IF($O$24=$X$20,Z31,IF($O$24=$AB$20,AD31,AH31)))) -> 0.0067 | R31: =IF(K31>Q31,"Excedeu limites",IF(K31<O31,"Abaixo do limite","ok")) -> ok | T31: 0.0005 | U31: 0.0067 | V31: 0.0067 | X31: 0.0005 | Y31: 0.0067 | Z31: 0.0067 | AB31: 0.0005 | AC31: 0.0067 | AD31: 0.0067 | AF31: 0.0005 | AG31: 0.0067 | AH31: 0.0067 | AI31: =Orç_analítico_Hab!M24/IF(Orç_analítico_Hab!M$430=0,1,Orç_analítico_Hab!M$430) -> 0 | AJ31: =AI31-ROUND(AI31,4)+AJ30 -> 0 | AK31: =ROUND(L31,2) -> 0
B32: 1.7 | C32: gestão de resíduos | K32: 0.0011 | L32: =ROUND(K32*FRE!$M$187,2) -> 0 | O32: =IF($O$24=$T$20,T32,IF($O$24=$X$20,X32,IF($O$24=$AB$20,AB32,AF32))) -> 0.0005 | P32: a | Q32: =IF(OR(FRE!$N$189="não",FRE!$N$189<"0"), IF($O$24=$T$20,U32,IF($O$24=$X$20,Y32,IF($O$24=$AB$20,AC32,AG32))), IF($O$24=$T$20,V32,IF($O$24=$X$20,Z32,IF($O$24=$AB$20,AD32,AH32)))) -> 0.0011 | R32: =IF(K32>Q32,"Excedeu limites",IF(K32<O32,"Abaixo do limite","ok")) -> ok | T32: 0.0005 | U32: 0.0011 | V32: 0.0011 | X32: 0.0005 | Y32: 0.0011 | Z32: 0.0011 | AB32: 0.0005 | AC32: 0.0011 | AD32: 0.0011 | AF32: 0.0005 | AG32: 0.0011 | AH32: 0.0011 | AI32: =Orç_analítico_Hab!M25/IF(Orç_analítico_Hab!M$430=0,1,Orç_analítico_Hab!M$430) -> 0 | AJ32: =AI32-ROUND(AI32,4)+AJ31 -> 0 | AK32: =ROUND(L32,2) -> 0
B33: 1.8 | C33: gestão da qualidade | K33: 0.0009 | L33: =ROUND(K33*FRE!$M$187,2) -> 0 | O33: =IF($O$24=$T$20,T33,IF($O$24=$X$20,X33,IF($O$24=$AB$20,AB33,AF33))) -> 0.0005 | P33: a | Q33: =IF(OR(FRE!$N$189="não",FRE!$N$189<"0"), IF($O$24=$T$20,U33,IF($O$24=$X$20,Y33,IF($O$24=$AB$20,AC33,AG33))), IF($O$24=$T$20,V33,IF($O$24=$X$20,Z33,IF($O$24=$AB$20,AD33,AH33)))) -> 0.0009 | R33: =IF(K33>Q33,"Excedeu limites",IF(K33<O33,"Abaixo do limite","ok")) -> ok | T33: 0.0005 | U33: 0.0009 | V33: 0.0009 | X33: 0.0005 | Y33: 0.0009 | Z33: 0.0009 | AB33: 0.0005 | AC33: 0.0009 | AD33: 0.0009 | AF33: 0.0005 | AG33: 0.0009 | AH33: 0.0009 | AI33: =Orç_analítico_Hab!M26/IF(Orç_analítico_Hab!M$430=0,1,Orç_analítico_Hab!M$430) -> 0 | AJ33: =AI33-ROUND(AI33,4)+AJ32 -> 0 | AK33: =ROUND(L33,2) -> 0
B34: 1.9 | C34: equipamentos de proteção coletivos | K34: 0.0006 | L34: =ROUND(K34*FRE!$M$187,2) -> 0 | O34: =IF($O$24=$T$20,T34,IF($O$24=$X$20,X34,IF($O$24=$AB$20,AB34,AF34))) -> 0 | P34: a | Q34: =IF(OR(FRE!$N$189="não",FRE!$N$189<"0"), IF($O$24=$T$20,U34,IF($O$24=$X$20,Y34,IF($O$24=$AB$20,AC34,AG34))), IF($O$24=$T$20,V34,IF($O$24=$X$20,Z34,IF($O$24=$AB$20,AD34,AH34)))) -> 0.0006 | R34: =IF(K34>Q34,"Excedeu limites",IF(K34<O34,"Abaixo do limite","ok")) -> ok | T34: 0 | U34: 0.0006 | V34: 0.0006 | X34: 0 | Y34: 0.0006 | Z34: 0.0006 | AB34: 0 | AC34: 0.0006 | AD34: 0.0006 | AF34: 0 | AG34: 0.0006 | AH34: 0.0006 | AI34: =Orç_analítico_Hab!M27/IF(Orç_analítico_Hab!M$430=0,1,Orç_analítico_Hab!M$430) -> 0 | AJ34: =AI34-ROUND(AI34,4)+AJ33 -> 0 | AK34: =ROUND(L34,2) -> 0
B35: 1.10 | C35: administração local (engenheiros, mestres, etc.) | K35: 0.07 | L35: =ROUND(K35*FRE!$M$187,2) -> 0 | O35: =IF($O$24=$T$20,T35,IF($O$24=$X$20,X35,IF($O$24=$AB$20,AB35,AF35))) -> 0.025 | P35: a | Q35: =IF(OR(FRE!$N$189="não",FRE!$N$189<"0"), IF($O$24=$T$20,U35,IF($O$24=$X$20,Y35,IF($O$24=$AB$20,AC35,AG35))), IF($O$24=$T$20,V35,IF($O$24=$X$20,Z35,IF($O$24=$AB$20,AD35,AH35)))) -> 0.07 | R35: =IF(K35>Q35,"Excedeu limites",IF(K35<O35,"Abaixo do limite","ok")) -> ok | T35: 0.025 | U35: 0.07 | V35: 0.07 | X35: 0.025 | Y35: 0.07 | Z35: 0.07 | AB35: 0.025 | AC35: 0.07 | AD35: 0.07 | AF35: 0.025 | AG35: 0.07 | AH35: 0.07 | AI35: =Orç_analítico_Hab!M28/IF(Orç_analítico_Hab!M$430=0,1,Orç_analítico_Hab!M$430) -> 0 | AJ35: =AI35-ROUND(AI35,4)+AJ34 -> 0 | AK35: =ROUND(L35,2) -> 0
B36: 2 | C36: FUNDAÇÕES E CONTENÇÕES | K36: =SUM(K37:K38) -> 0.11 | L36: =SUM(L37:L38) -> 0 | M36: =IF(SUM($L$25,$L$36,$L$39,$L$40,$L$45,$L$48,$L$55,$L$62,$L$71,$L$75)=0,0,M25+L36/SUM($L$25,$L$36,$L$39,$L$40,$L$45,$L$48,$L$55,$L$62,$L$71,$L$75)) -> 0 | AK36: =SUM(AK37:AK38) -> 0
B37: 2.1 | C37: Fundações | K37: 0.08 | L37: =ROUND(K37*FRE!$M$187,2) -> 0 | O37: =IF($O$24=$T$20,T37,IF($O$24=$X$20,X37,IF($O$24=$AB$20,AB37,AF37))) -> 0.03 | P37: a | Q37: =IF(OR(FRE!$N$189="não",FRE!$N$189<"0"), IF($O$24=$T$20,U37,IF($O$24=$X$20,Y37,IF($O$24=$AB$20,AC37,AG37))), IF($O$24=$T$20,V37,IF($O$24=$X$20,Z37,IF($O$24=$AB$20,AD37,AH37)))) -> 0.08 | R37: =IF(K37>Q37,"Excedeu limites",IF(K37<O37,"Abaixo do limite","ok")) -> ok | T37: 0.03 | U37: 0.08 | V37: 0.095 | X37: 0.03 | Y37: 0.08 | Z37: 0.095 | AB37: 0.03 | AC37: 0.07 | AD37: 0.085 | AF37: 0.03 | AG37: 0.08 | AH37: 0.095 | AI37: =SUM(Orç_analítico_Hab!M33:'Orç_analítico_Hab'!M52)/IF(Orç_analítico_Hab!M$430=0,1,Orç_analítico_Hab!M$430) -> 0 | AJ37: =AI37-ROUND(AI37,4)+AJ35 -> 0 | AK37: =ROUND(L37,2) -> 0
B38: 2.2 | C38: Contenções/arrimos especiais | K38: 0.03 | L38: =ROUND(K38*FRE!$M$187,2) -> 0 | O38: =IF($O$24=$T$20,T38,IF($O$24=$X$20,X38,IF($O$24=$AB$20,AB38,AF38))) -> 0 | P38: a | Q38: =IF(OR(FRE!$N$189="não",FRE!$N$189<"0"), IF($O$24=$T$20,U38,IF($O$24=$X$20,Y38,IF($O$24=$AB$20,AC38,AG38))), IF($O$24=$T$20,V38,IF($O$24=$X$20,Z38,IF($O$24=$AB$20,AD38,AH38)))) -> 0.03 | R38: =IF(K38>Q38,"Excedeu limites",IF(K38<O38,"Abaixo do limite","ok")) -> ok | T38: 0 | U38: 0.03 | V38: 0.035 | X38: 0 | Y38: 0.03 | Z38: 0.035 | AB38: 0 | AC38: 0.03 | AD38: 0.035 | AF38: 0 | AG38: 0.03 | AH38: 0.035 | AI38: =SUM(Orç_analítico_Hab!M55:'Orç_analítico_Hab'!M61)/IF(Orç_analítico_Hab!M$430=0,1,Orç_analítico_Hab!M$430) -> 0 | AJ38: =AI38-ROUND(AI38,4)+AJ37 -> 0 | AK38: =ROUND(L38,2) -> 0
B39: 3 | C39: SUPRAESTRUTURA | K39: =ROUND(AI39,4) -> 0 | L39: =ROUND(K39*FRE!$M$187,2) -> 0 | M39: =IF(SUM($L$25,$L$36,$L$39,$L$40,$L$45,$L$48,$L$55,$L$62,$L$71,$L$75)=0,0,M36+L39/SUM($L$25,$L$36,$L$39,$L$40,$L$45,$L$48,$L$55,$L$62,$L$71,$L$75)) -> 0 | O39: =IF($O$24=$T$20,T39,IF($O$24=$X$20,X39,IF($O$24=$AB$20,AB39,AF39))) -> 0.03 | P39: a | Q39: =IF(OR(FRE!$N$189="não",FRE!$N$189<"0"), IF($O$24=$T$20,U39,IF($O$24=$X$20,Y39,IF($O$24=$AB$20,AC39,AG39))), IF($O$24=$T$20,V39,IF($O$24=$X$20,Z39,IF($O$24=$AB$20,AD39,AH39)))) -> 0.15 | R39: =IF(K39>Q39,"Excedeu limites",IF(K39<O39,"Abaixo do limite","ok")) -> Abaixo do limite | T39: 0.03 | U39: 0.15 | V39: 0.175 | X39: 0.1 | Y39: 0.25 | Z39: 0.3 | AB39: 0.1 | AC39: 0.25 | AD39: 0.3 | AF39: 0.14 | AG39: 0.35 | AH39: 0.4 | AI39: =SUM(Orç_analítico_Hab!M65:'Orç_analítico_Hab'!M69)/IF(Orç_analítico_Hab!M$430=0,1,Orç_analítico_Hab!M$430) -> 0 | AJ39: =AI39-ROUND(AI39,4)+AJ38 -> 0 | AK39: =ROUND(L39,2) -> 0
B40: 4 | C40: PAREDES E PAINÉIS | K40: =SUM(K41:K44) -> 0.14 | L40: =SUM(L41:L44) -> 0 | M40: =IF(SUM($L$25,$L$36,$L$39,$L$40,$L$45,$L$48,$L$55,$L$62,$L$71,$L$75)=0,0,M39+L40/SUM($L$25,$L$36,$L$39,$L$40,$L$45,$L$48,$L$55,$L$62,$L$71,$L$75)) -> 0 | AK40: =SUM(AK41:AK44) -> 0
B41: 4.1 | C41: alvenaria / fechamentos | K41: 0.11 | L41: =ROUND(K41*FRE!$M$187,2) -> 0 | O41: =IF($O$24=$T$20,T41,IF($O$24=$X$20,X41,IF($O$24=$AB$20,AB41,AF41))) -> 0.06 | P41: a | Q41: =IF(OR(FRE!$N$189="não",FRE!$N$189<"0"), IF($O$24=$T$20,U41,IF($O$24=$X$20,Y41,IF($O$24=$AB$20,AC41,AG41))), IF($O$24=$T$20,V41,IF($O$24=$X$20,Z41,IF($O$24=$AB$20,AD41,AH41)))) -> 0.15 | R41: =IF(K41>Q41,"Excedeu limites",IF(K41<O41,"Abaixo do limite","ok")) -> ok | T41: 0.06 | U41: 0.15 | V41: 0.175 | X41: 0.04 | Y41: 0.15 | Z41: 0.18 | AB41: 0.02 | AC41: 0.08 | AD41: 0.095 | AF41: 0 | AG41: 0.005 | AH41: 0.005 | AI41: =SUM(Orç_analítico_Hab!M74:'Orç_analítico_Hab'!M81)/IF(Orç_analítico_Hab!M$430=0,1,Orç_analítico_Hab!M$430) -> 0 | AJ41: =AI41-ROUND(AI41,4)+AJ39 -> 0 | AK41: =ROUND(L41,2) -> 0
B42: 4.2 | C42: esquadrias metálicas | K42: 0.01 | L42: =ROUND(K42*FRE!$M$187,2) -> 0 | O42: =IF($O$24=$T$20,T42,IF($O$24=$X$20,X42,IF($O$24=$AB$20,AB42,AF42))) -> 0 | P42: a | Q42: =IF(OR(FRE!$N$189="não",FRE!$N$189<"0"), IF($O$24=$T$20,U42,IF($O$24=$X$20,Y42,IF($O$24=$AB$20,AC42,AG42))), IF($O$24=$T$20,V42,IF($O$24=$X$20,Z42,IF($O$24=$AB$20,AD42,AH42)))) -> 0.08 | R42: =IF(K42>Q42,"Excedeu limites",IF(K42<O42,"Abaixo do limite","ok")) -> ok | T42: 0 | U42: 0.08 | V42: 0.095 | X42: 0 | Y42: 0.08 | Z42: 0.095 | AB42: 0.02 | AC42: 0.1 | AD42: 0.12 | AF42: 0 | AG42: 0.08 | AH42: 0.095 | AI42: =SUM(Orç_analítico_Hab!M84:'Orç_analítico_Hab'!M102)/IF(Orç_analítico_Hab!M$430=0,1,Orç_analítico_Hab!M$430) -> 0 | AJ42: =AI42-ROUND(AI42,4)+AJ41 -> 0 | AK42: =ROUND(L42,2) -> 0
B43: 4.3 | C43: esquadrias de madeira | K43: 0.01 | L43: =ROUND(K43*FRE!$M$187,2) -> 0 | O43: =IF($O$24=$T$20,T43,IF($O$24=$X$20,X43,IF($O$24=$AB$20,AB43,AF43))) -> 0.01 | P43: a | Q43: =IF(OR(FRE!$N$189="não",FRE!$N$189<"0"), IF($O$24=$T$20,U43,IF($O$24=$X$20,Y43,IF($O$24=$AB$20,AC43,AG43))), IF($O$24=$T$20,V43,IF($O$24=$X$20,Z43,IF($O$24=$AB$20,AD43,AH43)))) -> 0.06 | R43: =IF(K43>Q43,"Excedeu limites",IF(K43<O43,"Abaixo do limite","ok")) -> ok | T43: 0.01 | U43: 0.06 | V43: 0.07 | X43: 0.01 | Y43: 0.06 | Z43: 0.07 | AB43: 0 | AC43: 0.04 | AD43: 0.045 | AF43: 0.01 | AG43: 0.06 | AH43: 0.07 | AI43: =SUM(Orç_analítico_Hab!M105:'Orç_analítico_Hab'!M123)/IF(Orç_analítico_Hab!M$430=0,1,Orç_analítico_Hab!M$430) -> 0 | AJ43: =AI43-ROUND(AI43,4)+AJ42 -> 0 | AK43: =ROUND(L43,2) -> 0
B44: 4.4 | C44: vidros / esquadrias especiais | K44: 0.01 | L44: =ROUND(K44*FRE!$M$187,2) -> 0 | O44: =IF($O$24=$T$20,T44,IF($O$24=$X$20,X44,IF($O$24=$AB$20,AB44,AF44))) -> 0 | P44: a | Q44: =IF(OR(FRE!$N$189="não",FRE!$N$189<"0"), IF($O$24=$T$20,U44,IF($O$24=$X$20,Y44,IF($O$24=$AB$20,AC44,AG44))), IF($O$24=$T$20,V44,IF($O$24=$X$20,Z44,IF($O$24=$AB$20,AD44,AH44)))) -> 0.03 | R44: =IF(K44>Q44,"Excedeu limites",IF(K44<O44,"Abaixo do limite","ok")) -> ok | T44: 0 | U44: 0.03 | V44: 0.035 | X44: 0 | Y44: 0.03 | Z44: 0.035 | AB44: 0.015 | AC44: 0.05 | AD44: 0.06 | AF44: 0 | AG44: 0.03 | AH44: 0.035 | AI44: =SUM(Orç_analítico_Hab!M126:'Orç_analítico_Hab'!M132)/IF(Orç_analítico_Hab!M$430=0,1,Orç_analítico_Hab!M$430) -> 0 | AJ44: =AI44-ROUND(AI44,4)+AJ43 -> 0 | AK44: =ROUND(L44,2) -> 0
B45: 5 | C45: COBERTURA E PROTEÇÕES | K45: =SUM(K46:K47) -> 0.03 | L45: =SUM(L46:L47) -> 0 | M45: =IF(SUM($L$25,$L$36,$L$39,$L$40,$L$45,$L$48,$L$55,$L$62,$L$71,$L$75)=0,0,M40+L45/SUM($L$25,$L$36,$L$39,$L$40,$L$45,$L$48,$L$55,$L$62,$L$71,$L$75)) -> 0 | AK45: =SUM(AK46:AK47) -> 0
B46: 5.1 | C46: telhados | K46: 0.02 | L46: =ROUND(K46*FRE!$M$187,2) -> 0 | O46: =IF($O$24=$T$20,T46,IF($O$24=$X$20,X46,IF($O$24=$AB$20,AB46,AF46))) -> 0 | P46: a | Q46: =IF(OR(FRE!$N$189="não",FRE!$N$189<"0"), IF($O$24=$T$20,U46,IF($O$24=$X$20,Y46,IF($O$24=$AB$20,AC46,AG46))), IF($O$24=$T$20,V46,IF($O$24=$X$20,Z46,IF($O$24=$AB$20,AD46,AH46)))) -> 0.15 | R46: =IF(K46>Q46,"Excedeu limites",IF(K46<O46,"Abaixo do limite","ok")) -> ok | T46: 0 | U46: 0.15 | V46: 0.175 | X46: 0 | Y46: 0.03 | Z46: 0.035 | AB46: 0 | AC46: 0.03 | AD46: 0.035 | AF46: 0 | AG46: 0.08 | AH46: 0.095 | AI46: =SUM(Orç_analítico_Hab!M137:'Orç_analítico_Hab'!M141)/IF(Orç_analítico_Hab!M$430=0,1,Orç_analítico_Hab!M$430) -> 0 | AJ46: =AI46-ROUND(AI46,4)+AJ44 -> 0 | AK46: =ROUND(L46,2) -> 0
B47: 5.2 | C47: impermeabilizações | K47: 0.01 | L47: =ROUND(K47*FRE!$M$187,2) -> 0 | O47: =IF($O$24=$T$20,T47,IF($O$24=$X$20,X47,IF($O$24=$AB$20,AB47,AF47))) -> 0.005 | P47: a | Q47: =IF(OR(FRE!$N$189="não",FRE!$N$189<"0"), IF($O$24=$T$20,U47,IF($O$24=$X$20,Y47,IF($O$24=$AB$20,AC47,AG47))), IF($O$24=$T$20,V47,IF($O$24=$X$20,Z47,IF($O$24=$AB$20,AD47,AH47)))) -> 0.03 | R47: =IF(K47>Q47,"Excedeu limites",IF(K47<O47,"Abaixo do limite","ok")) -> ok | T47: 0.005 | U47: 0.03 | V47: 0.035 | X47: 0.002 | Y47: 0.025 | Z47: 0.03 | AB47: 0.002 | AC47: 0.025 | AD47: 0.03 | AF47: 0.002 | AG47: 0.025 | AH47: 0.03 | AI47: =SUM(Orç_analítico_Hab!M144:'Orç_analítico_Hab'!M159)/IF(Orç_analítico_Hab!M$430=0,1,Orç_analítico_Hab!M$430) -> 0 | AJ47: =AI47-ROUND(AI47,4)+AJ46 -> 0 | AK47: =ROUND(L47,2) -> 0
B48: 6 | C48: REVESTIMENTOS | K48: =SUM(K49:K54) -> 0.185 | L48: =SUM(L49:L54) -> 0 | M48: =IF(SUM($L$25,$L$36,$L$39,$L$40,$L$45,$L$48,$L$55,$L$62,$L$71,$L$75)=0,0,M45+L48/SUM($L$25,$L$36,$L$39,$L$40,$L$45,$L$48,$L$55,$L$62,$L$71,$L$75)) -> 0 | AK48: =SUM(AK49:AK54) -> 0
B49: 6.1 | C49: revestimentos internos | K49: 0.05 | L49: =ROUND(K49*FRE!$M$187,2) -> 0 | O49: =IF($O$24=$T$20,T49,IF($O$24=$X$20,X49,IF($O$24=$AB$20,AB49,AF49))) -> 0.04 | P49: a | Q49: =IF(OR(FRE!$N$189="não",FRE!$N$189<"0"), IF($O$24=$T$20,U49,IF($O$24=$X$20,Y49,IF($O$24=$AB$20,AC49,AG49))), IF($O$24=$T$20,V49,IF($O$24=$X$20,Z49,IF($O$24=$AB$20,AD49,AH49)))) -> 0.08 | R49: =IF(K49>Q49,"Excedeu limites",IF(K49<O49,"Abaixo do limite","ok")) -> ok | T49: 0.04 | U49: 0.08 | V49: 0.095 | X49: 0.04 | Y49: 0.08 | Z49: 0.095 | AB49: 0.01 | AC49: 0.06 | AD49: 0.07 | AF49: 0.02 | AG49: 0.08 | AH49: 0.095 | AI49: =SUM(Orç_analítico_Hab!M164:'Orç_analítico_Hab'!M171)/IF(Orç_analítico_Hab!M$430=0,1,Orç_analítico_Hab!M$430) -> 0 | AJ49: =AI49-ROUND(AI49,4)+AJ47 -> 0 | AK49: =ROUND(L49,2) -> 0
B50: 6.2 | C50: azulejos | K50: 0.03 | L50: =ROUND(K50*FRE!$M$187,2) -> 0 | O50: =IF($O$24=$T$20,T50,IF($O$24=$X$20,X50,IF($O$24=$AB$20,AB50,AF50))) -> 0.03 | P50: a | Q50: =IF(OR(FRE!$N$189="não",FRE!$N$189<"0"), IF($O$24=$T$20,U50,IF($O$24=$X$20,Y50,IF($O$24=$AB$20,AC50,AG50))), IF($O$24=$T$20,V50,IF($O$24=$X$20,Z50,IF($O$24=$AB$20,AD50,AH50)))) -> 0.06 | R50: =IF(K50>Q50,"Excedeu limites",IF(K50<O50,"Abaixo do limite","ok")) -> ok | T50: 0.03 | U50: 0.06 | V50: 0.07 | X50: 0.025 | Y50: 0.06 | Z50: 0.07 | AB50: 0.01 | AC50: 0.06 | AD50: 0.07 | AF50: 0.025 | AG50: 0.06 | AH50: 0.07 | AI50: =SUM(Orç_analítico_Hab!M174:'Orç_analítico_Hab'!M182)/IF(Orç_analítico_Hab!M$430=0,1,Orç_analítico_Hab!M$430) -> 0 | AJ50: =AI50-ROUND(AI50,4)+AJ49 -> 0 | AK50: =ROUND(L50,2) -> 0
B51: 6.3 | C51: revestimentos externos | K51: 0.04 | L51: =ROUND(K51*FRE!$M$187,2) -> 0 | O51: =IF($O$24=$T$20,T51,IF($O$24=$X$20,X51,IF($O$24=$AB$20,AB51,AF51))) -> 0.04 | P51: a | Q51: =IF(OR(FRE!$N$189="não",FRE!$N$189<"0"), IF($O$24=$T$20,U51,IF($O$24=$X$20,Y51,IF($O$24=$AB$20,AC51,AG51))), IF($O$24=$T$20,V51,IF($O$24=$X$20,Z51,IF($O$24=$AB$20,AD51,AH51)))) -> 0.08 | R51: =IF(K51>Q51,"Excedeu limites",IF(K51<O51,"Abaixo do limite","ok")) -> ok | T51: 0.04 | U51: 0.08 | V51: 0.095 | X51: 0.04 | Y51: 0.06 | Z51: 0.07 | AB51: 0.04 | AC51: 0.08 | AD51: 0.095 | AF51: 0.02 | AG51: 0.06 | AH51: 0.07 | AI51: =SUM(Orç_analítico_Hab!M185:'Orç_analítico_Hab'!M191)/IF(Orç_analítico_Hab!M$430=0,1,Orç_analítico_Hab!M$430) -> 0 | AJ51: =AI51-ROUND(AI51,4)+AJ50 -> 0 | AK51: =ROUND(L51,2) -> 0
B52: 6.4 | C52: forros | K52: 0.005 | L52: =ROUND(K52*FRE!$M$187,2) -> 0 | O52: =IF($O$24=$T$20,T52,IF($O$24=$X$20,X52,IF($O$24=$AB$20,AB52,AF52))) -> 0.005 | P52: a | Q52: =IF(OR(FRE!$N$189="não",FRE!$N$189<"0"), IF($O$24=$T$20,U52,IF($O$24=$X$20,Y52,IF($O$24=$AB$20,AC52,AG52))), IF($O$24=$T$20,V52,IF($O$24=$X$20,Z52,IF($O$24=$AB$20,AD52,AH52)))) -> 0.04 | R52: =IF(K52>Q52,"Excedeu limites",IF(K52<O52,"Abaixo do limite","ok")) -> ok | T52: 0.005 | U52: 0.04 | V52: 0.045 | X52: 0.005 | Y52: 0.03 | Z52: 0.035 | AB52: 0.005 | AC52: 0.03 | AD52: 0.035 | AF52: 0 | AG52: 0.03 | AH52: 0.035 | AI52: =SUM(Orç_analítico_Hab!M194:'Orç_analítico_Hab'!M199)/IF(Orç_analítico_Hab!M$430=0,1,Orç_analítico_Hab!M$430) -> 0 | AJ52: =AI52-ROUND(AI52,4)+AJ51 -> 0 | AK52: =ROUND(L52,2) -> 0
B53: 6.5 | C53: pinturas | K53: 0.06 | L53: =ROUND(K53*FRE!$M$187,2) -> 0 | O53: =IF($O$24=$T$20,T53,IF($O$24=$X$20,X53,IF($O$24=$AB$20,AB53,AF53))) -> 0.06 | P53: a | Q53: =IF(OR(FRE!$N$189="não",FRE!$N$189<"0"), IF($O$24=$T$20,U53,IF($O$24=$X$20,Y53,IF($O$24=$AB$20,AC53,AG53))), IF($O$24=$T$20,V53,IF($O$24=$X$20,Z53,IF($O$24=$AB$20,AD53,AH53)))) -> 0.09 | R53: =IF(K53>Q53,"Excedeu limites",IF(K53<O53,"Abaixo do limite","ok")) -> ok | T53: 0.06 | U53: 0.09 | V53: 0.105 | X53: 0.05 | Y53: 0.09 | Z53: 0.1 | AB53: 0.025 | AC53: 0.09 | AD53: 0.1 | AF53: 0.07 | AG53: 0.12 | AH53: 0.14 | AI53: =SUM(Orç_analítico_Hab!M202:'Orç_analítico_Hab'!M217)/IF(Orç_analítico_Hab!M$430=0,1,Orç_analítico_Hab!M$430) -> 0 | AJ53: =AI53-ROUND(AI53,4)+AJ52 -> 0 | AK53: =ROUND(L53,2) -> 0
B54: 6.6 | C54: especiais / elementos fachadas | K54: 0 | L54: =ROUND(K54*FRE!$M$187,2) -> 0 | O54: =IF($O$24=$T$20,T54,IF($O$24=$X$20,X54,IF($O$24=$AB$20,AB54,AF54))) -> 0 | P54: a | Q54: =IF(OR(FRE!$N$189="não",FRE!$N$189<"0"), IF($O$24=$T$20,U54,IF($O$24=$X$20,Y54,IF($O$24=$AB$20,AC54,AG54))), IF($O$24=$T$20,V54,IF($O$24=$X$20,Z54,IF($O$24=$AB$20,AD54,AH54)))) -> 0.02 | R54: =IF(K54>Q54,"Excedeu limites",IF(K54<O54,"Abaixo do limite","ok")) -> ok | T54: 0 | U54: 0.02 | V54: 0.025 | X54: 0 | Y54: 0.05 | Z54: 0.06 | AB54: 0.01 | AC54: 0.05 | AD54: 0.06 | AF54: 0 | AG54: 0.05 | AH54: 0.06 | AI54: =SUM(Orç_analítico_Hab!M220:'Orç_analítico_Hab'!M227)/IF(Orç_analítico_Hab!M$430=0,1,Orç_analítico_Hab!M$430) -> 0 | AJ54: =AI54-ROUND(AI54,4)+AJ53 -> 0 | AK54: =ROUND(L54,2) -> 0
B55: 7 | C55: PAVIMENTAÇÃO | K55: =SUM(K56:K61) -> 0.06 | L55: =SUM(L56:L61) -> 0 | M55: =IF(SUM($L$25,$L$36,$L$39,$L$40,$L$45,$L$48,$L$55,$L$62,$L$71,$L$75)=0,0,M48+L55/SUM($L$25,$L$36,$L$39,$L$40,$L$45,$L$48,$L$55,$L$62,$L$71,$L$75)) -> 0 | AK55: =SUM(AK56:AK61) -> 0
...

Sheet Orç_analítico_Hab
A1: (escolha) | L1: Grau de sigilo
A2: Habitacional horizontal | E2: Orçamento Analítico Habitação | L2: #EXTERNO.CONFIDENCIAL
A3: Vertical: habit. / salas / misto
A4: Vertical andar livre | E4: =FRE!$D$4 -> Programa: | F4: =FRE!$E$4 -> Apoio à Produção de Imóveis - Pessoa Jurídica
A5: Vertical parede de concreto
I17: =FRE!N189 -> não | J17: Unidade | K17: Quantidade | L17: Custo unitário | M17: Custo total | N17: % do item
B18: 1 | C18: SERVIÇOS PRELIMINARES E GERAIS
B19: 1.1 | C19: serviços técnicos (projetos, orçamentos, levant. topog., sondagem, licenças e PCMAT) | M19: =ROUND(L19*K19,2) -> 0
B20: 1.2 | C20: instalações e canteiros (barracão, cercamento e placa da obra) | M20: =ROUND(L20*K20,2) -> 0
B21: 1.3 | C21: ligações provisórias (água, energia, telefone e esgoto) | M21: =ROUND(L21*K21,2) -> 0
B22: 1.4 | C22: manutenção canteiro/consumo | M22: =ROUND(L22*K22,2) -> 0
B23: 1.5 | C23: transportes máquinas e equipamentos | M23: =ROUND(L23*K23,2) -> 0
B24: 1.6 | C24: controle tecnológico | M24: =ROUND(L24*K24,2) -> 0
B25: 1.7 | C25: gestão de resíduos | M25: =ROUND(L25*K25,2) -> 0
B26: 1.8 | C26: gestão da qualidade | M26: =ROUND(L26*K26,2) -> 0
B27: 1.9 | C27: equipamentos de proteção coletivos | M27: =ROUND(L27*K27,2) -> 0
B28: 1.10 | C28: administração local (engenheiros, mestres, etc.) | M28: =ROUND(L28*K28,2) -> 0
C29: CUSTO TOTAL DO ITEM | M29: =SUM(M18:M28) -> 0 | N29: =IF($M$430=0,0,M29/$M$430) -> 0
B31: 2 | C31: FUNDAÇÃO E CONTENÇÕES
B32: 2.1 | C32: Trabalhos com terra
B33: 2.1.1 | C33: Demolições | M33: =ROUND(L33*K33,2) -> 0
B34: 2.1.2 | C34: Limpeza do terreno | M34: =ROUND(L34*K34,2) -> 0
B35: 2.1.3 | C35: Escavações mecânicas | M35: =ROUND(L35*K35,2) -> 0
B36: 2.1.4 | C36: Escavaçoes manuais | M36: =ROUND(L36*K36,2) -> 0
B37: 2.1.5 | C37: Aterro e apiloamento | M37: =ROUND(L37*K37,2) -> 0
B38: 2.1.6 | C38: Locação da Obra | D38: Trabalhos em | M38: =ROUND(L38*K38,2) -> 0
B39: 2.1.7 | C39: Desmonte em Rocha | M39: =ROUND(L39*K39,2) -> 0
B40: 2.1.8 | M40: =ROUND(L40*K40,2) -> 0
B41: 2.1.9 | M41: =ROUND(L41*K41,2) -> 0
B42: 2.1.10 | M42: =ROUND(L42*K42,2) -> 0
B44: 2.2 | C44: Fundações e outros serviços
B45: 2.2.1 | C45: Escoramento do Terreno vizinho | M45: =ROUND(L45*K45,2) -> 0
B46: 2.2.2 | C46: Reb. Lençol Freático/Drenagem | M46: =ROUND(L46*K46,2) -> 0
B47: 2.2.3 | C47: Fundações Profundas | M47: =ROUND(L47*K47,2) -> 0
B48: 2.2.4 | C48: Fundações Superficiais | M48: =ROUND(L48*K48,2) -> 0
B49: 2.2.5 | C49: Vigas, Baldrames e Alavancas | M49: =ROUND(L49*K49,2) -> 0
B50: 2.2.6 | M50: =ROUND(L50*K50,2) -> 0
B51: 2.2.7 | M51: =ROUND(L51*K51,2) -> 0
B52: 2.2.8 | M52: =ROUND(L52*K52,2) -> 0
B54: 2.3 | C54: Contenções / arrimos especiais
...

Sheet Orç_eventos_Infra
A1: (escolha) | L1: Grau de sigilo
A2: Habitacional horizontal | E2: Orçamento por Eventos da Infraestrutura | L2: #EXTERNO.CONFIDENCIAL
A3: Vertical: habit. / salas / misto
A4: Vertical andar livre | E4: =FRE!$D$4 -> Programa: | F4: =FRE!$E$4 -> Apoio à Produção de Imóveis - Pessoa Jurídica
A5: Vertical parede de concreto
J17: Unidade | K17: Quantidade | L17: Custo unitário | M17: Custo total | N17: % do item
B18: 1 | C18: TERRAPLENAGEM
B19: 1.1 | C19: ESTUDO DO SOLO (SONDAGEM, ENSAIOS, CONTROLE TECNOLÓGICO) | J19: vb | M19: =L19*K19 -> 0
B20: 1.2 | C20: TERRAPLENAGEM (CORTE E ATERRO) | J20: m3 | M20: =L20*K20 -> 0
B21: 1.3 | C21: PROTEÇÃO DE TALUDES (GRAMA, HIDROSSEMEADURA, ETC) | J21: m2 | M21: =L21*K21 -> 0
B22: 1.4 | M22: =L22*K22 -> 0
B23: 1.5 | M23: =L23*K23 -> 0
C24: CUSTO TOTAL DO ITEM | M24: =SUM(M18:M23) -> 0 | N24: =IF($M$91=0,0,M24/$M$91) -> 0
B26: 2 | C26: ÁGUA POTÁVEL
B27: 2.1 | C27: CAPTAÇÃO (EM REDE EXISTENTE, POÇO PROFUNDO, MANANCIAL, ETC) | M27: =L27*K27 -> 0
B28: 2.2 | C28: RESERVAÇÃO | J28: m3 | M28: =L28*K28 -> 0
B29: 2.3 | C29: REDE DE DISTRIBUIÇÃO DE ÁGUA | J29: m | M29: =L29*K29 -> 0
B30: 2.4 | C30: TRATAMENTO DA ÁGUA | J30: m3/s | M30: =L30*K30 -> 0
B31: 2.5 | M31: =L31*K31 -> 0
B32: 2.6 | M32: =L32*K32 -> 0
C33: CUSTO TOTAL DO ITEM | M33: =SUM(M26:M32) -> 0 | N33: =IF($M$91=0,0,M33/$M$91) -> 0
B35: 3 | C35: ESGOTO SANITÁRIO
B36: 3.1 | C36: REDE DE ESGOTAMENTO SANITÁRIO | J36: m | M36: =L36*K36 -> 0
B37: 3.2 | C37: ELEVATÓRIA | J37: m3/s | M37: =L37*K37 -> 0
B38: 3.3 | C38: TRATAMENTO DE EFLUENTES (FOSSA, SUMIDOURO, FILTRO, ETE) | J38: m3/s | M38: =L38*K38 -> 0
B39: 3.4 | M39: =L39*K39 -> 0
B40: 3.5 | M40: =L40*K40 -> 0
C41: CUSTO TOTAL DO ITEM | M41: =SUM(M35:M40) -> 0 | N41: =IF($M$91=0,0,M41/$M$91) -> 0
B43: 4 | C43: DRENAGEM DAS ÁGUAS PLUVIAIS
B44: 4.1 | C44: REDE DE DRENAGEM PLUVIAL | J44: m | M44: =L44*K44 -> 0
B45: 4.5 | C45: TERMINAL DE LANÇAMENTO | J45: und | M45: =L45*K45 -> 0
B46: 4.6 | M46: =L46*K46 -> 0
B47: 4.7 | M47: =L47*K47 -> 0
C48: CUSTO TOTAL DO ITEM | M48: =SUM(M43:M47) -> 0 | N48: =IF($M$91=0,0,M48/$M$91) -> 0
B50: 5 | C50: PAVIMENTAÇÃO
B51: 5.1 | C51: PAVIMENTAÇÃO EM | J51: m2 | M51: =L51*K51 -> 0
B52: 5.2 | C52: GUIAS E SARJETAS | J52: m | M52: =L52*K52 -> 0
B53: 5.3 | C53: PASSEIOS/CALÇADAS | J53: m2 | M53: =L53*K53 -> 0
B54: 5.4 | M54: =L54*K54 -> 0
B55: 5.5 | M55: =L55*K55 -> 0
...

Sheet Orç_analítico_Equipamen_Faixa_I
A1: (escolha) | M1: Grau de sigilo
A2: Habitacional horizontal | E2: Orçamento Analítico Equipamentos Comunitários e de Uso Comum | M2: #EXTERNO.CONFIDENCIAL
A3: Vertical: habit. / salas / misto
A4: Vertical andar livre | E4: =FRE!$D$4 -> Programa: | F4: =FRE!$E$4 -> Apoio à Produção de Imóveis - Pessoa Jurídica
A5: Vertical parede de concreto
J17: Unidade | K17: Quantidade | L17: Custo unitário | M17: Custo total | N17: % do item
B18: 1 | C18: SERVIÇOS PRELIMINARES E GERAIS
B19: 1.1 | C19: Serviços técnicos (levantamento topográfico, projetos,especificações, orç., cronograma) | M19: =L19*K19 -> 0
B20: 1.2 | C20: Despesas iniciais (cópias, licenças, taxas e impostos) | M20: =L20*K20 -> 0
B21: 1.3 | C21: Instalações provisórias (tapumes, barracão, água, luz, esgoto e placas) | M21: =L21*K21 -> 0
B22: 1.4 | C22: Máquinas e ferramentas (betoneira, vibrador, serra, bomba, carrinho, guincho) | M22: =L22*K22 -> 0
B23: 1.5 | C23: Consumos | M23: =L23*K23 -> 0
B24: 1.6 | C24: Limpeza da Obra | M24: =L24*K24 -> 0
B25: 1.7 | C25: Transportes | M25: =L25*K25 -> 0
B26: 1.8 | M26: =L26*K26 -> 0
B27: 1.9 | M27: =L27*K27 -> 0
B28: 1.10 | M28: =L28*K28 -> 0
C29: CUSTO TOTAL DO ITEM | M29: =SUM(M18:M28) -> 0 | N29: =IF($M$356=0,0,M29/$M$356) -> 0
B31: 2 | C31: FUNDAÇÕES E CONTENÇÕES
B32: 2.1 | C32: Trabalhos com terra
B33: 2.1.1 | C33: Demolições | M33: =L33*K33 -> 0
B34: 2.1.2 | C34: Limpeza do terreno | M34: =L34*K34 -> 0
B35: 2.1.3 | C35: Escavações mecânicas | M35: =L35*K35 -> 0
B36: 2.1.4 | C36: Escavaçoes manuais | M36: =L36*K36 -> 0
B37: 2.1.5 | C37: Aterro e apiloamento | M37: =L37*K37 -> 0
B38: 2.1.6 | C38: Locação da Obra | D38: Trabalhos em | M38: =L38*K38 -> 0
B39: 2.1.7 | C39: Desmonte em Rocha | M39: =L39*K39 -> 0
B40: 2.1.8 | M40: =L40*K40 -> 0
B41: 2.1.9 | M41: =L41*K41 -> 0
B43: 2.2 | C43: Fundações e outros serviços
B44: 2.2.1 | C44: Escoramento do Terreno vizinho | M44: =L44*K44 -> 0
B45: 2.2.2 | C45: Reb. Lençol Freático/Drenagem | M45: =L45*K45 -> 0
B46: 2.2.3 | C46: Fundações Profundas | M46: =L46*K46 -> 0
B47: 2.2.4 | C47: Fundações Superficiais | M47: =L47*K47 -> 0
B48: 2.2.5 | C48: Vigas, Baldrames e Alavancas | M48: =L48*K48 -> 0
B49: 2.2.6 | M49: =L49*K49 -> 0
B50: 2.2.7 | M50: =L50*K50 -> 0
C51: CUSTO TOTAL DO ITEM | M51: =SUM(M31:M50) -> 0 | N51: =IF($M$356=0,0,M51/$M$356) -> 0
B53: 3 | C53: SUPRAESTRUTURA
B54: 3.1 | C54: Concreto Armado | M54: =L54*K54 -> 0
...

Sheet Cronograma
A1: (escolha) | N1: Grau de sigilo
A2: cronograma inicial | E2: Cronograma físico-financeiro global | N2: #EXTERNO.CONFIDENCIAL
A3: reprogramação
A4: Vertical andar livre | E4: =FRE!$D$4 -> Programa: | F4: =FRE!$E$4 -> Apoio à Produção de Imóveis - Pessoa Jurídica
A5: Vertical parede de concreto
C17: Tipo do cronograma: | D17: cronograma inicial | H17: Data da contratação: | N17: Data da retirada da suspensiva:
B19: Custos | D19: =FRE!B186 -> Edificações | J19: =FRE!M187 -> 0 | L19: =IF(SUM($J$19:$K$21)=0,0,J19/SUM($J$19:$K$21)) -> 0
D20: =FRE!B189 -> Infraestrutura e urbanização | J20: =IF(FRE!$N$189="não",0,FRE!M190) -> 0 | L20: =IF(SUM($J$19:$K$21)=0,0,J20/SUM($J$19:$K$21)) -> 0
D21: =FRE!B192 -> Equipamentos comunitários | J21: =IF(FRE!$E$4=FRE!$A$7,FRE!M193,) -> 0 | L21: =IF(SUM($J$19:$K$21)=0,0,J21/SUM($J$19:$K$21)) -> 0
D23: Infraestrutura não incidente | J23: =SUM(J24:K26) -> 0 | L23: =IF($J$23=0,0,J23/$J$23) -> 0
D24: =IF(FRE!B209="","",FRE!B209) | J24: =FRE!G209 -> 0 | L24: =IF($J$23=0,0,J24/$J$23) -> 0
D25: =IF(FRE!B210="","",FRE!B210) | J25: =FRE!G210 -> 0 | L25: =IF($J$23=0,0,J25/$J$23) -> 0
D26: =IF(FRE!B211="","",FRE!B211) | J26: =FRE!G211 -> 0 | L26: =IF($J$23=0,0,J26/$J$23) -> 0
B27: =FRE!N189 -> não | C27: =FRE!E4 -> Apoio à Produção de Imóveis - Pessoa Jurídica | D27: =FRE!A6 -> Produção de Lotes Urbanizados - PRODULOTE - PJ | E27: =FRE!A7 -> PCVA - Recursos FAR
B28: Etapa | C28: =D19 -> Edificações | E28: =D20 -> Infraestrutura e urbanização | G28: =D21 -> Equipamentos comunitários | I28: Evolução física da obra | K28: Indique a etapa que terá habite-se e CND | M28: % de liberação financeira | O28: Infra não incidente
C29: % da etapa | D29: % acumulado | E29: % da etapa | F29: % acumulado | G29: % da etapa | H29: % acumulado | I29: % da etapa | J29: % acumulado | K29: Indique | L29: % acumulado | M29: % da etapa | N29: % acumulado | O29: % da etapa | P29: % acumulado
B30: Executado | C30: 0 | D30: =SUM(C$30:C30) -> 0 | F30: =SUM(E$30:E30) -> 0 | H30: =SUM(G$30:G30) -> 0 | I30: =IF(SUM($J$19:$K$21)=0,0,(C30*$J$19+E30*$J$20+G30*$J$21)/SUM($J$19:$K$21)) -> 0 | J30: =SUM(I$30:I30) -> 0 | L30: =IF(COUNTA($K$30:$K$78)=0,0,COUNTA($K$30:K30)/COUNTA($K$30:$K$78)) -> 0 | M30: =IF(L30>=100%,5%,IF(N29>=95%,0,IF(J30<=95%,I30,(I30-(J30-95%))))) -> 0 | N30: =IF(L30>=100%,J30,IF(J30>95%,95%,J30)) -> 0 | P30: =SUM(O$30:O30) -> 0
B31: 1 | C31: 0.0327 | D31: =SUM(C$30:C31) -> 0.0327 | F31: =SUM(E$30:E31) -> 0 | H31: =SUM(G$30:G31) -> 0 | I31: =IF(SUM($J$19:$K$21)=0,0,(C31*$J$19+E31*$J$20+G31*$J$21)/SUM($J$19:$K$21)) -> 0 | J31: =SUM(I$30:I31) -> 0 | L31: =IF(COUNTA($K$30:$K$78)=0,0,COUNTA($K$30:K31)/COUNTA($K$30:$K$78)) -> 0 | M31: =IF(L31>=100%,5%,IF(N30>=95%,0,IF(J31<=95%,I31,(I31-(J31-95%))))) -> 0 | N31: =IF(L31>=100%,J31,IF(J31>95%,95%,J31)) -> 0 | P31: =SUM(O$30:O31) -> 0
B32: 2 | C32: 0.0327 | D32: =SUM(C$30:C32) -> 0.0654 | F32: =SUM(E$30:E32) -> 0 | H32: =SUM(G$30:G32) -> 0 | I32: =IF(SUM($J$19:$K$21)=0,0,(C32*$J$19+E32*$J$20+G32*$J$21)/SUM($J$19:$K$21)) -> 0 | J32: =SUM(I$30:I32) -> 0 | L32: =IF(COUNTA($K$30:$K$78)=0,0,COUNTA($K$30:K32)/COUNTA($K$30:$K$78)) -> 0 | M32: =IF(L32>=100%,5%,IF(N31>=95%,0,IF(J32<=95%,I32,(I32-(J32-95%))))) -> 0 | N32: =IF(L32>=100%,J32,IF(J32>95%,95%,J32)) -> 0 | P32: =SUM(O$30:O32) -> 0
B33: 3 | C33: 0.0327 | D33: =SUM(C$30:C33) -> 0.0981 | F33: =SUM(E$30:E33) -> 0 | H33: =SUM(G$30:G33) -> 0 | I33: =IF(SUM($J$19:$K$21)=0,0,(C33*$J$19+E33*$J$20+G33*$J$21)/SUM($J$19:$K$21)) -> 0 | J33: =SUM(I$30:I33) -> 0 | L33: =IF(COUNTA($K$30:$K$78)=0,0,COUNTA($K$30:K33)/COUNTA($K$30:$K$78)) -> 0 | M33: =IF(L33>=100%,5%,IF(N32>=95%,0,IF(J33<=95%,I33,(I33-(J33-95%))))) -> 0 | N33: =IF(L33>=100%,J33,IF(J33>95%,95%,J33)) -> 0 | P33: =SUM(O$30:O33) -> 0
B34: 4 | C34: 0.0327 | D34: =SUM(C$30:C34) -> 0.1308 | F34: =SUM(E$30:E34) -> 0 | H34: =SUM(G$30:G34) -> 0 | I34: =IF(SUM($J$19:$K$21)=0,0,(C34*$J$19+E34*$J$20+G34*$J$21)/SUM($J$19:$K$21)) -> 0 | J34: =SUM(I$30:I34) -> 0 | L34: =IF(COUNTA($K$30:$K$78)=0,0,COUNTA($K$30:K34)/COUNTA($K$30:$K$78)) -> 0 | M34: =IF(L34>=100%,5%,IF(N33>=95%,0,IF(J34<=95%,I34,(I34-(J34-95%))))) -> 0 | N34: =IF(L34>=100%,J34,IF(J34>95%,95%,J34)) -> 0 | P34: =SUM(O$30:O34) -> 0
B35: 5 | C35: 0.0327 | D35: =SUM(C$30:C35) -> 0.1635 | F35: =SUM(E$30:E35) -> 0 | H35: =SUM(G$30:G35) -> 0 | I35: =IF(SUM($J$19:$K$21)=0,0,(C35*$J$19+E35*$J$20+G35*$J$21)/SUM($J$19:$K$21)) -> 0 | J35: =SUM(I$30:I35) -> 0 | L35: =IF(COUNTA($K$30:$K$78)=0,0,COUNTA($K$30:K35)/COUNTA($K$30:$K$78)) -> 0 | M35: =IF(L35>=100%,5%,IF(N34>=95%,0,IF(J35<=95%,I35,(I35-(J35-95%))))) -> 0 | N35: =IF(L35>=100%,J35,IF(J35>95%,95%,J35)) -> 0 | P35: =SUM(O$30:O35) -> 0
B36: 6 | C36: 0.0327 | D36: =SUM(C$30:C36) -> 0.1962 | F36: =SUM(E$30:E36) -> 0 | H36: =SUM(G$30:G36) -> 0 | I36: =IF(SUM($J$19:$K$21)=0,0,(C36*$J$19+E36*$J$20+G36*$J$21)/SUM($J$19:$K$21)) -> 0 | J36: =SUM(I$30:I36) -> 0 | L36: =IF(COUNTA($K$30:$K$78)=0,0,COUNTA($K$30:K36)/COUNTA($K$30:$K$78)) -> 0 | M36: =IF(L36>=100%,5%,IF(N35>=95%,0,IF(J36<=95%,I36,(I36-(J36-95%))))) -> 0 | N36: =IF(L36>=100%,J36,IF(J36>95%,95%,J36)) -> 0 | P36: =SUM(O$30:O36) -> 0
B37: 7 | C37: 0.0327 | D37: =SUM(C$30:C37) -> 0.2289 | F37: =SUM(E$30:E37) -> 0 | H37: =SUM(G$30:G37) -> 0 | I37: =IF(SUM($J$19:$K$21)=0,0,(C37*$J$19+E37*$J$20+G37*$J$21)/SUM($J$19:$K$21)) -> 0 | J37: =SUM(I$30:I37) -> 0 | L37: =IF(COUNTA($K$30:$K$78)=0,0,COUNTA($K$30:K37)/COUNTA($K$30:$K$78)) -> 0 | M37: =IF(L37>=100%,5%,IF(N36>=95%,0,IF(J37<=95%,I37,(I37-(J37-95%))))) -> 0 | N37: =IF(L37>=100%,J37,IF(J37>95%,95%,J37)) -> 0 | P37: =SUM(O$30:O37) -> 0
B38: 8 | C38: 0.0327 | D38: =SUM(C$30:C38) -> 0.2616 | F38: =SUM(E$30:E38) -> 0 | H38: =SUM(G$30:G38) -> 0 | I38: =IF(SUM($J$19:$K$21)=0,0,(C38*$J$19+E38*$J$20+G38*$J$21)/SUM($J$19:$K$21)) -> 0 | J38: =SUM(I$30:I38) -> 0 | L38: =IF(COUNTA($K$30:$K$78)=0,0,COUNTA($K$30:K38)/COUNTA($K$30:$K$78)) -> 0 | M38: =IF(L38>=100%,5%,IF(N37>=95%,0,IF(J38<=95%,I38,(I38-(J38-95%))))) -> 0 | N38: =IF(L38>=100%,J38,IF(J38>95%,95%,J38)) -> 0 | P38: =SUM(O$30:O38) -> 0
B39: 9 | C39: 0.0327 | D39: =SUM(C$30:C39) -> 0.2943 | F39: =SUM(E$30:E39) -> 0 | H39: =SUM(G$30:G39) -> 0 | I39: =IF(SUM($J$19:$K$21)=0,0,(C39*$J$19+E39*$J$20+G39*$J$21)/SUM($J$19:$K$21)) -> 0 | J39: =SUM(I$30:I39) -> 0 | L39: =IF(COUNTA($K$30:$K$78)=0,0,COUNTA($K$30:K39)/COUNTA($K$30:$K$78)) -> 0 | M39: =IF(L39>=100%,5%,IF(N38>=95%,0,IF(J39<=95%,I39,(I39-(J39-95%))))) -> 0 | N39: =IF(L39>=100%,J39,IF(J39>95%,95%,J39)) -> 0 | P39: =SUM(O$30:O39) -> 0
B40: 10 | C40: 0.0327 | D40: =SUM(C$30:C40) -> 0.327 | F40: =SUM(E$30:E40) -> 0 | H40: =SUM(G$30:G40) -> 0 | I40: =IF(SUM($J$19:$K$21)=0,0,(C40*$J$19+E40*$J$20+G40*$J$21)/SUM($J$19:$K$21)) -> 0 | J40: =SUM(I$30:I40) -> 0 | L40: =IF(COUNTA($K$30:$K$78)=0,0,COUNTA($K$30:K40)/COUNTA($K$30:$K$78)) -> 0 | M40: =IF(L40>=100%,5%,IF(N39>=95%,0,IF(J40<=95%,I40,(I40-(J40-95%))))) -> 0 | N40: =IF(L40>=100%,J40,IF(J40>95%,95%,J40)) -> 0 | P40: =SUM(O$30:O40) -> 0
B41: 11 | C41: 0.0327 | D41: =SUM(C$30:C41) -> 0.3597 | F41: =SUM(E$30:E41) -> 0 | H41: =SUM(G$30:G41) -> 0 | I41: =IF(SUM($J$19:$K$21)=0,0,(C41*$J$19+E41*$J$20+G41*$J$21)/SUM($J$19:$K$21)) -> 0 | J41: =SUM(I$30:I41) -> 0 | L41: =IF(COUNTA($K$30:$K$78)=0,0,COUNTA($K$30:K41)/COUNTA($K$30:$K$78)) -> 0 | M41: =IF(L41>=100%,5%,IF(N40>=95%,0,IF(J41<=95%,I41,(I41-(J41-95%))))) -> 0 | N41: =IF(L41>=100%,J41,IF(J41>95%,95%,J41)) -> 0 | P41: =SUM(O$30:O41) -> 0
B42: 12 | C42: 0.0327 | D42: =SUM(C$30:C42) -> 0.3924 | F42: =SUM(E$30:E42) -> 0 | H42: =SUM(G$30:G42) -> 0 | I42: =IF(SUM($J$19:$K$21)=0,0,(C42*$J$19+E42*$J$20+G42*$J$21)/SUM($J$19:$K$21)) -> 0 | J42: =SUM(I$30:I42) -> 0 | L42: =IF(COUNTA($K$30:$K$78)=0,0,COUNTA($K$30:K42)/COUNTA($K$30:$K$78)) -> 0 | M42: =IF(L42>=100%,5%,IF(N41>=95%,0,IF(J42<=95%,I42,(I42-(J42-95%))))) -> 0 | N42: =IF(L42>=100%,J42,IF(J42>95%,95%,J42)) -> 0 | P42: =SUM(O$30:O42) -> 0
... B58: 28 | C58: 0.0327 | D58: =SUM(C$30:C58) -> 0.9156 | F58: =SUM(E$30:E58) -> 0 | H58: =SUM(G$30:G58) -> 0 | I58: =IF(SUM($J$19:$K$21)=0,0,(C58*$J$19+E58*$J$20+G58*$J$21)/SUM($J$19:$K$21)) -> 0 | J58: =SUM(I$30:I58) -> 0 | L58: =IF(COUNTA($K$30:$K$78)=0,0,COUNTA($K$30:K58)/COUNTA($K$30:$K$78)) -> 0 | M58: =IF(L58>=100%,5%,IF(N57>=95%,0,IF(J58<=95%,I58,(I58-(J58-95%))))) -> 0 | N58: =IF(L58>=100%,J58,IF(J58>95%,95%,J58)) -> 0 | P58: =SUM(O$30:O58) -> 0
B59: 29 | C59: 0.0344 | D59: =SUM(C$30:C59) -> 0.95 | F59: =SUM(E$30:E59) -> 0 | H59: =SUM(G$30:G59) -> 0 | I59: =IF(SUM($J$19:$K$21)=0,0,(C59*$J$19+E59*$J$20+G59*$J$21)/SUM($J$19:$K$21)) -> 0 | J59: =SUM(I$30:I59) -> 0 | K59: HABITE-SE E CND | L59: =IF(COUNTA($K$30:$K$78)=0,0,COUNTA($K$30:K59)/COUNTA($K$30:$K$78)) -> 1 | M59: =IF(L59>=100%,5%,IF(N58>=95%,0,IF(J59<=95%,I59,(I59-(J59-95%))))) -> 0.05 | N59: =IF(L59>=100%,J59,IF(J59>95%,95%,J59)) -> 0 | P59: =SUM(O$30:O59) -> 0
B60: 30 | C60: 0.05 | D60: =SUM(C$30:C60) -> 1 | F60: =SUM(E$30:E60) -> 0 | H60: =SUM(G$30:G60) -> 0 | I60: =IF(SUM($J$19:$K$21)=0,0,(C60*$J$19+E60*$J$20+G60*$J$21)/SUM($J$19:$K$21)) -> 0 | J60: =SUM(I$30:I60) -> 0 | L60: =IF(COUNTA($K$30:$K$78)=0,0,COUNTA($K$30:K60)/COUNTA($K$30:$K$78)) -> 1 | M60: =IF(L60>=100%,5%,IF(N59>=95%,0,IF(J60<=95%,I60,(I60-(J60-95%))))) -> 0.05 | N60: =IF(L60>=100%,J60,IF(J60>95%,95%,J60)) -> 0 | P60: =SUM(O$30:O60) -> 0
B61: 31 | D61: =SUM(C$30:C61) -> 1 | F61: =SUM(E$30:E61) -> 0 | H61: =SUM(G$30:G61) -> 0 | I61: =IF(SUM($J$19:$K$21)=0,0,(C61*$J$19+E61*$J$20+G61*$J$21)/SUM($J$19:$K$21)) -> 0 | J61: =SUM(I$30:I61) -> 0 | L61: =IF(COUNTA($K$30:$K$78)=0,0,COUNTA($K$30:K61)/COUNTA($K$30:$K$78)) -> 1 | M61: =IF(L61>=100%,5%,IF(N60>=95%,0,IF(J61<=95%,I61,(I61-(J61-95%))))) -> 0.05 | N61: =IF(L61>=100%,J61,IF(J61>95%,95%,J61)) -> 0 | P61: =SUM(O$30:O61) -> 0
B62: 32 | D62: =SUM(C$30:C62) -> 1 | F62: =SUM(E$30:E62) -> 0 | H62: =SUM(G$30:G62) -> 0 | I62: =IF(SUM($J$19:$K$21)=0,0,(C62*$J$19+E62*$J$20+G62*$J$21)/SUM($J$19:$K$21)) -> 0 | J62: =SUM(I$30:I62) -> 0 | L62: =IF(COUNTA($K$30:$K$78)=0,0,COUNTA($K$30:K62)/COUNTA($K$30:$K$78)) -> 1 | M62: =IF(L62>=100%,5%,IF(N61>=95%,0,IF(J62<=95%,I62,(I62-(J62-95%))))) -> 0.05 | N62: =IF(L62>=100%,J62,IF(J62>95%,95%,J62)) -> 0 | P62: =SUM(O$30:O62) -> 0
B63: 33 | D63: =SUM(C$30:C63) -> 1 | F63: =SUM(E$30:E63) -> 0 | H63: =SUM(G$30:G63) -> 0 | I63: =IF(SUM($J$19:$K$21)=0,0,(C63*$J$19+E63*$J$20+G63*$J$21)/SUM($J$19:$K$21)) -> 0 | J63: =SUM(I$30:I63) -> 0 | L63: =IF(COUNTA($K$30:$K$78)=0,0,COUNTA($K$30:K63)/COUNTA($K$30:$K$78)) -> 1 | M63: =IF(L63>=100%,5%,IF(N62>=95%,0,IF(J63<=95%,I63,(I63-(J63-95%))))) -> 0.05 | N63: =IF(L63>=100%,J63,IF(J63>95%,95%,J63)) -> 0 | P63: =SUM(O$30:O63) -> 0
B64: 34 | D64: =SUM(C$30:C64) -> 1 | F64: =SUM(E$30:E64) -> 0 | H64: =SUM(G$30:G64) -> 0 | I64: =IF(SUM($J$19:$K$21)=0,0,(C64*$J$19+E64*$J$20+G64*$J$21)/SUM($J$19:$K$21)) -> 0 | J64: =SUM(I$30:I64) -> 0 | L64: =IF(COUNTA($K$30:$K$78)=0,0,COUNTA($K$30:K64)/COUNTA($K$30:$K$78)) -> 1 | M64: =IF(L64>=100%,5%,IF(N63>=95%,0,IF(J64<=95%,I64,(I64-(J64-95%))))) -> 0.05 | N64: =IF(L64>=100%,J64,IF(J64>95%,95%,J64)) -> 0 | P64: =SUM(O$30:O64) -> 0
B65: 35 | D65: =SUM(C$30:C65) -> 1 | F65: =SUM(E$30:E65) -> 0 | H65: =SUM(G$30:G65) -> 0 | I65: =IF(SUM($J$19:$K$21)=0,0,(C65*$J$19+E65*$J$20+G65*$J$21)/SUM($J$19:$K$21)) -> 0 | J65: =SUM(I$30:I65) -> 0 | L65: =IF(COUNTA($K$30:$K$78)=0,0,COUNTA($K$30:K65)/COUNTA($K$30:$K$78)) -> 1 | M65: =IF(L65>=100%,5%,IF(N64>=95%,0,IF(J65<=95%,I65,(I65-(J65-95%))))) -> 0.05 | N65: =IF(L65>=100%,J65,IF(J65>95%,95%,J65)) -> 0 | P65: =SUM(O$30:O65) -> 0
B66: 36 | D66: =SUM(C$30:C66) -> 1 | F66: =SUM(E$30:E66) -> 0 | H66: =SUM(G$30:G66) -> 0 | I66: =IF(SUM($J$19:$K$21)=0,0,(C66*$J$19+E66*$J$20+G66*$J$21)/SUM($J$19:$K$21)) -> 0 | J66: =SUM(I$30:I66) -> 0 | L66: =IF(COUNTA($K$30:$K$78)=0,0,COUNTA($K$30:K66)/COUNTA($K$30:$K$78)) -> 1 | M66: =IF(L66>=100%,5%,IF(N65>=95%,0,IF(J66<=95%,I66,(I66-(J66-95%))))) -> 0.05 | N66: =IF(L66>=100%,J66,IF(J66>95%,95%,J66)) -> 0 | P66: =SUM(O$30:O66) -> 0
B67: 37 | D67: =SUM(C$30:C67) -> 1 | F67: =SUM(E$30:E67) -> 0 | H67: =SUM(G$30:G67) -> 0 | I67: =IF(SUM($J$19:$K$21)=0,0,(C67*$J$19+E67*$J$20+G67*$J$21)/SUM($J$19:$K$21)) -> 0 | J67: =SUM(I$30:I67) -> 0 | L67: =IF(COUNTA($K$30:$K$78)=0,0,COUNTA($K$30:K67)/COUNTA($K$30:$K$78)) -> 1 | M67: =IF(L67>=100%,5%,IF(N66>=95%,0,IF(J67<=95%,I67,(I67-(J67-95%))))) -> 0.05 | N67: =IF(L67>=100%,J67,IF(J67>95%,95%,J67)) -> 0 | P67: =SUM(O$30:O67) -> 0
B68: 38 | D68: =SUM(C$30:C68) -> 1 | F68: =SUM(E$30:E68) -> 0 | H68: =SUM(G$30:G68) -> 0 | I68: =IF(SUM($J$19:$K$21)=0,0,(C68*$J$19+E68*$J$20+G68*$J$21)/SUM($J$19:$K$21)) -> 0 | J68: =SUM(I$30:I68) -> 0 | L68: =IF(COUNTA($K$30:$K$78)=0,0,COUNTA($K$30:K68)/COUNTA($K$30:$K$78)) -> 1 | M68: =IF(L68>=100%,5%,IF(N67>=95%,0,IF(J68<=95%,I68,(I68-(J68-95%))))) -> 0.05 | N68: =IF(L68>=100%,J68,IF(J68>95%,95%,J68)) -> 0 | P68: =SUM(O$30:O68) -> 0
...
