Workbook

Sheet CAPA
B1: RESUMO DE ÁREAS E FRAÇÕES IDEAIS
B3: LOCALIZAÇÃO: | C3: {RUA}, {COMPLEMENTO}; {SETOR} - {CIDADE}
B4: Área do Terreno: | D4: =G10 -> 0 | E4: m²
B5: Área total construída: | D5: =D10 -> 0 | E5: m²
B7: UNIDADES | D7: ÁREA CONSTRUIDA (m2) PRIVATIVA + COMUM | E7: ÁREA DESCOBERTA NÃO CONSTRUIDA (m2) PRIVATIVA + COMUM | F7: TOTAL (m2) | G7: FRAÇÃO IDEAL
G8: TOTAL (m2) | H8: %
B9: FRAÇÃO 1 | C9: CASA 1 | D9: ({ÁREA CONSTRUÍDA PRIVATIVA}+{ÁREA CONSTRUÍDA COMUM}) | E9: ({ÁREA DESCOBERTA PRIVATIVA}+{ÁREA DESCOBERTA COMUM}) | F9: =SUM(E9,D9) -> 0 | G9: =F9 -> 0 | H9: =SUM(G9/G10) -> #DIV/0!
B10: TOTAL | D10: =SUM(D9:D9) -> 0 | E10: =SUM(E9:E9) -> 0 | F10: =SUM(F9:F9) -> 0 | G10: =SUM(G9:G9) -> 0 | H10: =SUM(H9:H9) -> #DIV/0!
B11: {CIDADE} , {DATA HOJE}
B13: ____________________________________________
B14: {RESPONSÁVEL TÉCNICO}
B15: {CREA}

Sheet INFORMAÇÕES PRELIMINARES
B2: NBR 12.721 - INFORMAÇÕES PRELIMINARES | K2: FOLHA No | L2: 1
B4: 1. | C4: INCORPORADOR
C5: 1.1 | D5: Nome: | F5: {IMCORPORADOR}
C6: 1.2 | D6: CNPJ / CPF: | F6: {DOC. INCORPORADOR}
C7: 1.3 | D7: Endereço:
B9: 2. | C9: RESPONSABILIDADE TÉCNICA PELAS INFORMAÇÕES E CÁLCULOS
C10: 2.1 | D10: Profissional Resposável Técnico: | G10: =CAPA!B14 -> {RESPONSÁVEL TÉCNICO}
C11: 2.2 | D11: Número de registro profissional no CREA: | G11: =CAPA!B15 -> {CREA}
C12: 2.3 | D12: Anotação de Responsabilidade Técnica (ART.):
C13: 2.4 | D13: Endereço:
B15: 3. | C15: DADOS DO PROJETO / IMÓVEL
C16: 3.1 | D16: Nome do Edifício: | G16: {NOME DO EMPREENDIMENTO}
C17: 3.2 | D17: Local da Construção: | G17: =CAPA!C3 -> {RUA}, {COMPLEMENTO}; {SETOR} - {CIDADE}
C19: 3.3 | D19: Cidade / UF: | G19: SENADOR CANEDO | L19: GO
C20: 3.4 | D20: Designação Projeto-padrão da NBR 12.721 mais semelhante ao imóvel | G20: R | H20: X | I20: CS | K20: CL
G21: CG | I21: CP | K21: CP1Q
C22: 3.5 | D22: Quantidade de unidades autônomas: | G22: {Nº DE UNIDADES} UNIDADES ( CASA 01 A {Nº DE UNIDADES})
C23: 3.6 | D23: Padrão de Acabamento: | G23: NORMAL
C24: 3.7 | D24: Números de Pavimentos: | G24: 01 PAVIMENTO ( TÉRREO)
C25: 3.8 | D25: Quantidade de Vagas de estacionamento para Veículos:
D26: 3.8.1 | E26: Vagas de Estacionamento (Unidade Autônoma) | I26: 01 VAGA POR CASA
D27: 3.8.2 | E27: Vagas de Estacionamento (acessório de Unidade Autônoma)
D28: 3.8.3 | E28: Vagas de Estacionamento (áreas de uso comum)
C29: 3.9 | D29: Área do Lote / Terreno: | H29: =CAPA!D4 -> 0 | J29: m²
C30: 3.10 | D30: Data de aprovação do projeto arquitetônico:
C31: 3.11 | D31: Número do Alvará de aprovação do projeto arquitetônico:
B32: 4. | C32: INFORMAÇÕES PLANILHAS / QUADROS
B33: Esta é a primeira folha de um total de | F33: 10 | G33: folhas, todas numeradas seguidamente e assinadas conjuntamente
B34: pelo profissional responsável técnico, incorporador / proprietário, para arquivamento e registro junto ao competente Registro de
B35: Imóveis, em atendimento ao disposto na Lei 4.591, de 16 de dezembro de 1.964.
B36: 5. | C36: DATA, LOCAL, ASSINATURAS E CARIMBOS
B37: =CAPA!B11 -> {CIDADE} , {DATA HOJE}
B41: INCORPORADOR / PROPRIETARIO: | G41: ____________________________________________
G42: =F5 -> {IMCORPORADOR}
B47: PROFISSIONAL RESPONSÁVEL: | G47: ____________________________________________
G48: =CAPA!B14 -> {RESPONSÁVEL TÉCNICO}
B51: Obs.: Os quadros apresentados neste Anexo poderão ser reproduzidos mantendo-se o formato original, sendo vedada a alteração da numeração de quadros e colunas, designações e especificações

Sheet QUADRO I
B2: INFORMAÇÕES PARA ARQUIVO NO REGISTRO DE IMÓVEIS
B3: (Lei 4.591 - 16/12/64 - Art. 32 e ABNT NBR 12721)
B4: QUADRO I - Cálculo das Áreas nos Pavimentos e da Área Global - Colunas 1 a 18 | P4: FOLHA No | R4: =('INFORMAÇÕES PRELIMINARES'!L2)+1 -> 2
B5: LOCAL DO IMÓVEL: | D5: =CAPA!C3 -> {RUA}, {COMPLEMENTO}; {SETOR} - {CIDADE} | P5: Adotar numeração seguida do quadro I ao VIII
P6: Total de folhas: | R6: 10
B7: INCORPORADOR | M7: Profissional Responsável:
B8: Nome: | C8: =('INFORMAÇÕES PRELIMINARES'!F5) -> {IMCORPORADOR} | M8: Nome: | N8: =('INFORMAÇÕES PRELIMINARES'!G10) -> {RESPONSÁVEL TÉCNICO}
B9: Assinatura: | M9: Assinatura:
B10: Data: | C10: {DATA HOJE} | M10: Data: | N10: =('QUADRO I'!$C$10) -> {DATA HOJE} | Q10: Registro no CREA: | S10: =('INFORMAÇÕES PRELIMINARES'!G11) -> {CREA}
C11: ÁREAS DE DIVISÃO NÃO PROPORCIONAL | M11: ÁREAS DE DIVISÃO PROPORCIONAL | R11: ÁREA DO PAVIMENTO | T11: QUANTIDADE (número de pavimentos idênticos)
B12: Pavimento | C12: ÁREA PRIVATIVA | H12: ÁREA DE USO COMUM | M12: ÁREAS DE USO COMUM
C13: Coberta padrão | D13: Coberta de padrão diferente ou descoberta | F13: TOTAIS | H13: Coberta padrão | I13: Coberta de padrão diferente ou descoberta | K13: TOTAIS | M13: Coberta padrão | N13: Coberta de padrão diferente ou descoberta | P13: TOTAIS
D14: Real | E14: Equivalente | F14: Real (2+3) | G14: Equivalente em área de custo padrão (2+4) | I14: Real | J14: Equivalente | K14: Real (7+8) | L14: Equivalente em área de custo padrão (7+9) | N14: Real | O14: Equivalente | P14: Real (12+13) | Q14: Equivalente em área de custo padrão (12+14) | R14: Real (5+10+15) | S14: Equivalente em área de custo padrão (6+11+16)
B15: 1 | C15: 2 | D15: 3 | E15: 4 | F15: 5 | G15: 6 | H15: 7 | I15: 8 | J15: 9 | K15: 10 | L15: 11 | M15: 12 | N15: 13 | O15: 14 | P15: 15 | Q15: 16 | R15: 17 | S15: 18
B16: TÉRREO | C16: =CAPA!D10 -> 0 | F16: =SUM(C16+D16) -> 0 | G16: =SUM(C16+E16) -> 0 | K16: =SUM(H16+I16) -> 0 | L16: =SUM(H16+J16) -> 0 | P16: =SUM(M16+N16) -> 0 | Q16: =SUM(M16+O16) -> 0 | R16: =SUM(F16+K16+P16) -> 0 | S16: =SUM(G16+L16+Q16) -> 0
F17: =SUM(C17+D17) -> 0 | G17: =SUM(C17+E17) -> 0 | K17: =SUM(H17+I17) -> 0 | L17: =SUM(H17+J17) -> 0 | P17: =SUM(M17+N17) -> 0 | Q17: =SUM(M17+O17) -> 0 | R17: =SUM(F17+K17+P17) -> 0 | S17: =SUM(G17+L17+Q17) -> 0
F18: =SUM(C18+D18) -> 0 | G18: =SUM(C18+E18) -> 0 | K18: =SUM(H18+I18) -> 0 | L18: =SUM(H18+J18) -> 0 | P18: =SUM(M18+N18) -> 0 | Q18: =SUM(M18+O18) -> 0 | R18: =SUM(F18+K18+P18) -> 0 | S18: =SUM(G18+L18+Q18) -> 0
F19: =SUM(C19+D19) -> 0 | G19: =SUM(C19+E19) -> 0 | K19: =SUM(H19+I19) -> 0 | L19: =SUM(H19+J19) -> 0 | P19: =SUM(M19+N19) -> 0 | Q19: =SUM(M19+O19) -> 0 | R19: =SUM(F19+K19+P19) -> 0 | S19: =SUM(G19+L19+Q19) -> 0
F20: =SUM(C20+D20) -> 0 | G20: =SUM(C20+E20) -> 0 | K20: =SUM(H20+I20) -> 0 | L20: =SUM(H20+J20) -> 0 | P20: =SUM(M20+N20) -> 0 | Q20: =SUM(M20+O20) -> 0 | R20: =SUM(F20+K20+P20) -> 0 | S20: =SUM(G20+L20+Q20) -> 0
F21: =SUM(C21+D21) -> 0 | G21: =SUM(C21+E21) -> 0 | K21: =SUM(H21+I21) -> 0 | L21: =SUM(H21+J21) -> 0 | P21: =SUM(M21+N21) -> 0 | Q21: =SUM(M21+O21) -> 0 | R21: =SUM(F21+K21+P21) -> 0 | S21: =SUM(G21+L21+Q21) -> 0
F22: =SUM(C22+D22) -> 0 | G22: =SUM(C22+E22) -> 0 | K22: =SUM(H22+I22) -> 0 | L22: =SUM(H22+J22) -> 0 | P22: =SUM(M22+N22) -> 0 | Q22: =SUM(M22+O22) -> 0 | R22: =SUM(F22+K22+P22) -> 0 | S22: =SUM(G22+L22+Q22) -> 0
F23: =SUM(C23+D23) -> 0 | G23: =SUM(C23+E23) -> 0 | K23: =SUM(H23+I23) -> 0 | L23: =SUM(H23+J23) -> 0 | P23: =SUM(M23+N23) -> 0 | Q23: =SUM(M23+O23) -> 0 | R23: =SUM(F23+K23+P23) -> 0 | S23: =SUM(G23+L23+Q23) -> 0
F24: =SUM(C24+D24) -> 0 | G24: =SUM(C24+E24) -> 0 | K24: =SUM(H24+I24) -> 0 | L24: =SUM(H24+J24) -> 0 | P24: =SUM(M24+N24) -> 0 | Q24: =SUM(M24+O24) -> 0 | R24: =SUM(F24+K24+P24) -> 0 | S24: =SUM(G24+L24+Q24) -> 0
F25: =SUM(C25+D25) -> 0 | G25: =SUM(C25+E25) -> 0 | K25: =SUM(H25+I25) -> 0 | L25: =SUM(H25+J25) -> 0 | P25: =SUM(M25+N25) -> 0 | Q25: =SUM(M25+O25) -> 0 | R25: =SUM(F25+K25+P25) -> 0 | S25: =SUM(G25+L25+Q25) -> 0
F26: =SUM(C26+D26) -> 0 | G26: =SUM(C26+E26) -> 0 | K26: =SUM(H26+I26) -> 0 | L26: =SUM(H26+J26) -> 0 | P26: =SUM(M26+N26) -> 0 | Q26: =SUM(M26+O26) -> 0 | R26: =SUM(F26+K26+P26) -> 0 | S26: =SUM(G26+L26+Q26) -> 0
F27: =SUM(C27+D27) -> 0 | G27: =SUM(C27+E27) -> 0 | K27: =SUM(H27+I27) -> 0 | L27: =SUM(H27+J27) -> 0 | P27: =SUM(M27+N27) -> 0 | Q27: =SUM(M27+O27) -> 0 | R27: =SUM(F27+K27+P27) -> 0 | S27: =SUM(G27+L27+Q27) -> 0
F28: =SUM(C28+D28) -> 0 | G28: =SUM(C28+E28) -> 0 | K28: =SUM(H28+I28) -> 0 | L28: =SUM(H28+J28) -> 0 | P28: =SUM(M28+N28) -> 0 | Q28: =SUM(M28+O28) -> 0 | R28: =SUM(F28+K28+P28) -> 0 | S28: =SUM(G28+L28+Q28) -> 0
... F37: =SUM(C37+D37) -> 0 | G37: =SUM(C37+E37) -> 0 | K37: =SUM(H37+I37) -> 0 | L37: =SUM(H37+J37) -> 0 | P37: =SUM(M37+N37) -> 0 | Q37: =SUM(M37+O37) -> 0 | R37: =SUM(F37+K37+P37) -> 0 | S37: =SUM(G37+L37+Q37) -> 0
B39: TOTAIS | C39: =CAPA!D10 -> 0 | D39: =SUMPRODUCT(D16:D38,$T16:$T38) -> 0 | E39: =SUMPRODUCT(E16:E38,$T16:$T38) -> 0 | F39: =CAPA!D10 -> 0 | G39: =CAPA!D10 -> 0 | H39: =SUMPRODUCT(H16:H38,$T16:$T38) -> 0 | I39: =SUMPRODUCT(I16:I38,$T16:$T38) -> 0 | J39: =SUMPRODUCT(J16:J38,$T16:$T38) -> 0 | K39: =SUMPRODUCT(K16:K38,$T16:$T38) -> 0 | L39: =SUMPRODUCT(L16:L38,$T16:$T38) -> 0 | M39: =SUMPRODUCT(M16:M38,$T16:$T38) -> 0 | N39: =SUMPRODUCT(N16:N38,$T16:$T38) -> 0 | O39: =SUMPRODUCT(O16:O38,$T16:$T38) -> 0 | ... Q39: =SUMPRODUCT(Q16:Q38,$T16:$T38) -> 0 | R39: =CAPA!D10 -> 0 | S39: =CAPA!D10 -> 0
B40: ÁREA REAL GLOBAL (Total da coluna 17) | F40: =R39 -> 0 | L40: ÁREA EQUIVALENTE GLOBAL (Total de Coluna 18) | Q40: =S39 -> 0
A41: OBSERVAÇÕES

Sheet QUADRO II
B2: INFORMAÇÕES PARA ARQUIVO NO REGISTRO DE IMÓVEIS
B3: (Lei 4.591 - 16/12/64 - Art. 32 e ABNT NBR 12721)
B4: QUADRO II - Cálculo das Áreas das Unidades Autônomas - Colunas 19 a 38 | R4: FOLHA No | T4: =('QUADRO I'!R4)+1 -> 3
B5: LOCAL DO IMÓVEL: | D5: =('QUADRO I'!$D$5) -> {RUA}, {COMPLEMENTO}; {SETOR} - {CIDADE} | R5: Adotar numeração seguida do quadro I ao VIII
R6: Total de folhas: | T6: =('QUADRO I'!$R$6) -> 10
B7: INCORPORADOR | N7: Profissional Responsável:
B8: Nome: | C8: =('QUADRO I'!$C$8) -> {IMCORPORADOR} | N8: Nome: | O8: =('QUADRO I'!$N$8) -> {RESPONSÁVEL TÉCNICO}
B9: Assinatura: | N9: Assinatura:
B10: Data: | C10: =('QUADRO I'!$C$10) -> {DATA HOJE} | N10: Data: | O10: =('QUADRO I'!$N$10) -> {DATA HOJE} | S10: =('QUADRO I'!$Q$10) -> Registro no CREA: | U10: =('QUADRO I'!$S$10) -> {CREA}
B11: Unidade | C11: ÁREAS DE DIVISÃO NÃO PROPORCIONAL | N11: Coeficien-te de proporcio-nalidade % | O11: ÁREAS DE DIVISÃO PROPORCIONAL | T11: ÁREA DA UNIDADE | V11: QUANTIDADE (número de unidades idênticas)
C12: ÁREA PRIVATIVA | H12: ÁREA DE USO COMUM | M12: Área total equivalen-te em área de custo padrão (24+29) | O12: ÁREAS DE USO COMUM
C13: Coberta Padrão | D13: Coberta de padrão diferente ou descoberta | F13: TOTAIS | H13: Coberta Padrão | I13: Coberta de padrão diferente ou descoberta | K13: TOTAIS | O13: Coberta Padrão | P13: Coberta de padrão diferente ou descoberta | R13: TOTAIS
D14: Real | E14: Equivalen-te | F14: Real (20+21) | G14: Equivalen-te em área de custo padrão (20+22) | I14: Real | J14: Equivalen-te | K14: Real (25+26) | L14: Equivalen-te em área de custo padrão (25+27) | P14: Real | Q14: Equivalen-te | R14: Real (32+33) | S14: Equivalen-te em área de custo padrão (32+34) | T14: Real (23+28+35) | U14: Equivalen-te em área de custo padrão (30+36)
N15: (30 / ∑30) | O15: (31 x ∑12) | P15: (31 x ∑13) | Q15: (31 x ∑14)
B16: 19 | C16: 20 | D16: 21 | E16: 22 | F16: 23 | G16: 24 | H16: 25 | I16: 26 | J16: 27 | K16: 28 | L16: 29 | M16: 30 | N16: 31 | O16: 32 | P16: 33 | Q16: 34 | R16: 35 | S16: 36 | T16: 37 | U16: 38
B17: CASA 01 | C17: =CAPA!D9 -> ({ÁREA CONSTRUÍDA PRIVATIVA}+{ÁREA CONSTRUÍDA COMUM}) | D17: =CAPA!E9 -> ({ÁREA DESCOBERTA PRIVATIVA}+{ÁREA DESCOBERTA COMUM}) | F17: =SUM(C17+D17) -> #VALUE! | G17: =SUM(C17+E17) -> #VALUE! | K17: =SUM(H17+I17) -> 0 | L17: =SUM(H17+J17) -> 0 | M17: =SUM(G17+L17) -> #VALUE! | N17: =CAPA!H9 -> #DIV/0! | O17: =ROUND('QUADRO II'!N17*'QUADRO I'!$M$39,2) -> #DIV/0! | P17: =ROUND('QUADRO II'!N17*'QUADRO I'!$N$39,2) -> #DIV/0! | Q17: =ROUND('QUADRO II'!N17*'QUADRO I'!$O$39,2) -> #DIV/0! | R17: =SUM(O17+P17) -> #DIV/0! | S17: =SUM(O17+Q17) -> #DIV/0! | T17: =SUM(F17+K17+R17) -> #VALUE! | U17: =SUM(M17+S17) -> #VALUE! | V17: 1
B19: TOTAIS | C19: =SUMPRODUCT(C17:C18,$V17:$V18) -> 0 | D19: =SUMPRODUCT(D17:D18,$V17:$V18) -> 0 | E19: =SUMPRODUCT(E17:E18,$V17:$V18) -> 0 | F19: =SUMPRODUCT(F17:F18,$V17:$V18) -> #VALUE! | G19: =SUMPRODUCT(G17:G18,$V17:$V18) -> #VALUE! | H19: =SUMPRODUCT(H17:H18,$V17:$V18) -> 0 | I19: =SUMPRODUCT(I17:I18,$V17:$V18) -> 0 | J19: =SUMPRODUCT(J17:J18,$V17:$V18) -> 0 | ... U19: =SUMPRODUCT(U17:U18,$V17:$V18) -> #VALUE! | V19: =SUM(V17:V18) -> 1
B20: ÁREA REAL GLOBAL (Total da coluna 37) | G20: =T19 -> #VALUE! | M20: ÁREA EQUIVALENTE GLOBAL (Total de Coluna 38) | S20: =U19 -> #VALUE!
A21: OBSERVAÇÕES

Sheet QUADRO III
B2: INFORMAÇÕES PARA ARQUIVO NO REGISTRO DE IMÓVEIS
B3: (Lei 4.591 - 16/12/64 - Art. 32 e ABNT NBR 12721)
B4: QUADRO III - Avaliação do Custo Global e Unitário da Construção | I4: Adotar numeração seguida do quadro I ao VIII
B5: Local do imóvel | D5: =('QUADRO I'!$D$5) -> {RUA}, {COMPLEMENTO}; {SETOR} - {CIDADE} | I5: Total de folhas: | L5: =('QUADRO I'!$R$6) -> 10
I6: Folha No | L6: =('QUADRO II'!T4)+1 -> 4
C7: INCORPORADOR | G7: Profissional Responsável:
B8: Nome: | D8: =('QUADRO I'!$C$8) -> {IMCORPORADOR} | G8: Nome: | H8: =('QUADRO I'!$N$8) -> {RESPONSÁVEL TÉCNICO}
B9: Assinatura: | G9: Assinatura:
B10: Data: | D10: =('QUADRO I'!$C$10) -> {DATA HOJE} | G10: Data: | H10: =('QUADRO I'!$N$10) -> {DATA HOJE} | I10: =('QUADRO I'!$Q$10) -> Registro no CREA: | L10: =('QUADRO I'!$S$10) -> {CREA}
B11: INFORMAÇÕES GERAIS | C11: 1. Projeto-padrão (Lei 4.591, Art. 53 § 1) que mais se assemelha ao da incorporação projetada
C12: CLASSIFICAÇÃO GERAL | G12: USO RESIDENCIAL
C13: Designação | D13: Padrão de acabamento | E13: Número de pavimentos | F13: Área equivalente total do projeto-padrão adotado | G13: Dependências de uso privativo da unidade autônoma
G15: Quartos | H15: Salas | I15: Banheiros ou WC | K15: Suíte
C18: PIS | D18: B | E18: 1 | F18: =CAPA!D9 -> ({ÁREA CONSTRUÍDA PRIVATIVA}+{ÁREA CONSTRUÍDA COMUM}) | G18: PREENCHER | H18: PREENCHER | I18: PREENCHER | K18: PREENCHER
C22: 2. Sindicato que forneceu o Custo Unitário Básico: | G22: SINDUSCON
C23: 3. Custo Unitário Básico para o mês de: | G23: PREENCHER | J23: R$ por m2 | K23: = | L23: PREENCHER
C24: 4. Áreas Globais do Prédio Projetado
D25: 4.1 Área Real Privativa, Global (QI, E5) | H25: =('QUADRO I'!F39) -> 0 | I25: m2 | L25: =ROUND(100*H25/H27,2) -> #DIV/0! | M25: %
D26: 4.2 Áreal Real de Uso Comum, Global (QI, E10 + E15) | H26: ='QUADRO I'!K39+'QUADRO I'!P39 -> 0 | I26: m2 | L26: =ROUND(100*H26/H27,2) -> #DIV/0! | M26: %
D27: 4.3 Área Real, Global (QI, E17) | H27: =('QUADRO I'!R39) -> 0 | I27: m2 | L27: 100 | M27: %
D28: 4.4 Área Equivalente* Privativa Global (QI, E6) | H28: =('QUADRO I'!G39) -> 0 | I28: m2 | L28: =ROUND(100*H28/H30,2) -> #DIV/0! | M28: %
D29: 4.5 Áreal Equivalente* de Uso Comum Global (QI, E11 + E16) | H29: ='QUADRO I'!L39+'QUADRO I'!Q39 -> 0 | I29: m2 | L29: =ROUND(100*H29/H30,2) -> #DIV/0! | M29: %
D30: 4.6 Áreal Equivalente* Global (QI, E18) | H30: =('QUADRO I'!S39) -> 0 | I30: m2 | L30: 100 | M30: %
D31: * obs: áreas equivalentes em área de custo padrão
B32: AVALIAÇÃO DO CUSTO GLOBAL DA CONSTRUÇÃO E DO CUSTO POR m2 DE CONSTRUÇÃO | C32: 5. Custo Básico Global da Edificação (4.6 x Custo Unitário Básico (3)) | K32: R$ | L32: =ROUND(L23*H30,2) -> #VALUE!
D33: 5.1 Composição do Custo Global básico da Edificação
E34: 5.1.1 Custo básico de Materiais e outros (5. X % Mat. do CUB inf. em 3.) | I34: R$ | J34: =ROUND($L$32*L34/100,2) -> #VALUE! | L34: =100*(P34)/$L$23 -> #VALUE! | M34: % | P34: =SUM(0+0+0) -> 0
E35: 5.1.2 Custo básico de Mão-de-Obra (5. X % Mão-de-Obra do CUB inf. em 3.) | I35: R$ | J35: =ROUND($L$32*L35/100,2) -> #VALUE! | L35: =100*(P35)/$L$23 -> #VALUE! | M35: % | P35: =SUM(0) -> 0
C36: 6. Parcelas Adicionais não Consideradas no Projeto-padrão
D37: 6.1 Fundações | K37: R$
D38: 6.2 Elevador(es) | K38: R$
D39: 6.3 Equipamentos e Instalações, tais como:
E40: 6.3.1 Fogões | K40: R$
E41: 6.3.2 Aquecedores | K41: R$
E42: 6.3.3 Bombas de Recalque | K42: R$
E43: 6.3.4 Incineração | K43: R$
E44: 6.3.5 Ar condicionado | K44: R$
E45: 6.3.6 Calefação | K45: R$
E46: 6.3.7 Ventilação e Exaustão | K46: R$
E47: 6.3.8 Outros (Discriminar) | K47: R$
...

Sheet QUADRO IV A
B1: INFORMAÇÕES PARA ARQUIVO NO REGISTRO DE IMÓVEIS
B2: (Lei 4.591 - 16/12/64 - Art. 32 e ABNT NBR 12721)
B3: QUADRO IV A - Avaliação do Custo de Cosntrução de cada Unidade Autônoma e cálculo do rerrateio de Sub-rogação - Colunas 39 a 52 | M3: Folha No | N3: =('QUADRO III'!L6)+1 -> 5
B4: LOCAL DO IMÓVEL: | D4: =('QUADRO I'!$D$5) -> {RUA}, {COMPLEMENTO}; {SETOR} - {CIDADE} | M4: Adotar numeração seguida
M5: Total de folhas: | N5: =('QUADRO I'!$R$6) -> 10
B6: INCORPORADOR | H6: Profissional Responsável:
B7: Nome: | C7: =('QUADRO I'!$C$8) -> {IMCORPORADOR} | H7: Nome: | I7: =('QUADRO I'!$N$8) -> {RESPONSÁVEL TÉCNICO}
B8: Assinatura: | H8: Assinatura:
B9: Data: | C9: =('QUADRO I'!$C$10) -> {DATA HOJE} | H9: Data: | I9: =('QUADRO I'!$N$10) -> {DATA HOJE} | K9: =('QUADRO I'!$Q$10) -> Registro no CREA: | M9: =('QUADRO I'!$S$10) -> {CREA}
B10: Designação da unidade | C10: Custo de Construção da Unidade Autônoma | F10: Rerrateio do custo (quando houver unidade(s) dada(s) em pagamento do terreno) | M10: Quantidade (número de unidades idênticas)
C11: Área equivalente em área de custo padrão das unidades | D11: CUSTO | E11: Coeficiente de proporcionali-dade (para rateio do custo da construção) | F11: Coeficiente de proporcionali-dade (das unidades que suportam o custo da construção) | G11: Coeficiente de rateio de construção total (rerrateio do coeficiente de proporcionalidade: Incorpora coeficiente das unidades dadas em pagamento do terreno) | H11: Área Equivalente em Área de Custo Padrão Total (rerrateio das áreas equivalentes em área de custo: Área Própria + quota da Área Sub-rogada) | I11: Custo de Construção total (rerrateio do custo) | J11: Custo da sub-rogação suportado por cada unidade | K11: Área real das unidades sub-rogadas | L11: Quota da área real dada em pagamento do terreno | M11: Total (total de unidades idênticas sub-rogadas ou não) | N11: Sub-rogadas | O11: Diferença (unidades que suportam o custo da edificação)
B12: (QII - 19) | C12: (QII - 38) | D12: (31 x item 13 QIII) | E12: (QII - 31) | F12: (42) | G12: (43 / ∑43) | H12: (44 x ∑40) | I12: (44 x item 13 QIII) | J12: (46 - 41) | K12: (QII - 37) | L12: (44 x ∑48) | O12: (50 - 51)
B13: 39 | C13: 40 | D13: 41 | E13: 42 | F13: 43 | G13: 44 | H13: 45 | I13: 46 | J13: 47 | K13: 48 | L13: 49 | M13: 50 | N13: 51 | O13: 52
B14: =('QUADRO II'!B17) -> CASA 01 | C14: =('QUADRO II'!U17) -> #VALUE! | D14: ='QUADRO III'!L32*0.0161290322580645 -> #VALUE! | E14: =('QUADRO II'!N17) -> #DIV/0! | L14: =ROUND(G14*$K$76,2) -> 0 | M14: =('QUADRO II'!V17) -> 1 | O14: =SUM(M14-N14) -> 1
B15: =('QUADRO II'!#REF!) -> #REF! | C15: =('QUADRO II'!#REF!) -> #REF! | D15: ='QUADRO III'!L32*0.0161290322580645 -> #VALUE! | E15: =('QUADRO II'!#REF!) -> #REF! | L15: =ROUND(G15*$K$76,2) -> 0 | M15: =('QUADRO II'!#REF!) -> #REF! | O15: =SUM(M15-N15) -> #REF!
B16: =('QUADRO II'!#REF!) -> #REF! | C16: =('QUADRO II'!#REF!) -> #REF! | D16: ='QUADRO III'!L32*0.0161290322580645 -> #VALUE! | E16: =('QUADRO II'!#REF!) -> #REF! | L16: =ROUND(G16*$K$76,2) -> 0 | M16: =('QUADRO II'!#REF!) -> #REF! | O16: =SUM(M16-N16) -> #REF!
B17: =('QUADRO II'!#REF!) -> #REF! | C17: =('QUADRO II'!#REF!) -> #REF! | D17: ='QUADRO III'!L32*0.0161290322580645 -> #VALUE! | E17: =('QUADRO II'!#REF!) -> #REF! | L17: =ROUND(G17*$K$76,2) -> 0 | M17: =('QUADRO II'!#REF!) -> #REF! | O17: =SUM(M17-N17) -> #REF!
B18: =('QUADRO II'!#REF!) -> #REF! | C18: =('QUADRO II'!#REF!) -> #REF! | D18: ='QUADRO III'!L32*0.0161290322580645 -> #VALUE! | E18: =('QUADRO II'!#REF!) -> #REF! | L18: =ROUND(G18*$K$76,2) -> 0 | M18: =('QUADRO II'!#REF!) -> #REF! | O18: =SUM(M18-N18) -> #REF!
B19: =('QUADRO II'!#REF!) -> #REF! | C19: =('QUADRO II'!#REF!) -> #REF! | D19: ='QUADRO III'!L32*0.0161290322580645 -> #VALUE! | E19: =('QUADRO II'!#REF!) -> #REF! | L19: =ROUND(G19*$K$76,2) -> 0 | M19: =('QUADRO II'!#REF!) -> #REF! | O19: =SUM(M19-N19) -> #REF!
B20: =('QUADRO II'!#REF!) -> #REF! | C20: =('QUADRO II'!#REF!) -> #REF! | D20: ='QUADRO III'!L32*0.0161290322580645 -> #VALUE! | E20: =('QUADRO II'!#REF!) -> #REF! | L20: =ROUND(G20*$K$76,2) -> 0 | M20: =('QUADRO II'!#REF!) -> #REF! | O20: =SUM(M20-N20) -> #REF!
B21: =('QUADRO II'!#REF!) -> #REF! | C21: =('QUADRO II'!#REF!) -> #REF! | D21: ='QUADRO III'!L32*0.0161290322580645 -> #VALUE! | E21: =('QUADRO II'!#REF!) -> #REF! | L21: =ROUND(G21*$K$76,2) -> 0 | M21: =('QUADRO II'!#REF!) -> #REF! | O21: =SUM(M21-N21) -> #REF!
B22: =('QUADRO II'!#REF!) -> #REF! | C22: =('QUADRO II'!#REF!) -> #REF! | D22: ='QUADRO III'!L32*0.0161290322580645 -> #VALUE! | E22: =('QUADRO II'!#REF!) -> #REF! | L22: =ROUND(G22*$K$76,2) -> 0 | M22: =('QUADRO II'!#REF!) -> #REF! | O22: =SUM(M22-N22) -> #REF!
B23: =('QUADRO II'!#REF!) -> #REF! | C23: =('QUADRO II'!#REF!) -> #REF! | D23: ='QUADRO III'!L32*0.0161290322580645 -> #VALUE! | E23: =('QUADRO II'!#REF!) -> #REF! | L23: =ROUND(G23*$K$76,2) -> 0 | M23: =('QUADRO II'!#REF!) -> #REF! | O23: =SUM(M23-N23) -> #REF!
B24: =('QUADRO II'!#REF!) -> #REF! | C24: =('QUADRO II'!#REF!) -> #REF! | D24: ='QUADRO III'!L32*0.0161290322580645 -> #VALUE! | E24: =('QUADRO II'!#REF!) -> #REF! | L24: =ROUND(G24*$K$76,2) -> 0 | M24: =('QUADRO II'!#REF!) -> #REF! | O24: =SUM(M24-N24) -> #REF!
B25: =('QUADRO II'!#REF!) -> #REF! | C25: =('QUADRO II'!#REF!) -> #REF! | D25: ='QUADRO III'!L32*0.0161290322580645 -> #VALUE! | E25: =('QUADRO II'!#REF!) -> #REF! | L25: =ROUND(G25*$K$76,2) -> 0 | M25: =('QUADRO II'!#REF!) -> #REF! | O25: =SUM(M25-N25) -> #REF!
B26: =('QUADRO II'!#REF!) -> #REF! | C26: =('QUADRO II'!#REF!) -> #REF! | D26: ='QUADRO III'!L32*0.0161290322580645 -> #VALUE! | E26: =('QUADRO II'!#REF!) -> #REF! | L26: =ROUND(G26*$K$76,2) -> 0 | M26: =('QUADRO II'!#REF!) -> #REF! | O26: =SUM(M26-N26) -> #REF!
B27: =('QUADRO II'!#REF!) -> #REF! | C27: =('QUADRO II'!#REF!) -> #REF! | D27: ='QUADRO III'!L32*0.0161290322580645 -> #VALUE! | E27: =('QUADRO II'!#REF!) -> #REF! | L27: =ROUND(G27*$K$76,2) -> 0 | M27: =('QUADRO II'!#REF!) -> #REF! | O27: =SUM(M27-N27) -> #REF!
B28: =('QUADRO II'!#REF!) -> #REF! | C28: =('QUADRO II'!#REF!) -> #REF! | D28: ='QUADRO III'!L32*0.0161290322580645 -> #VALUE! | E28: =('QUADRO II'!#REF!) -> #REF! | L28: =ROUND(G28*$K$76,2) -> 0 | M28: =('QUADRO II'!#REF!) -> #REF! | O28: =SUM(M28-N28) -> #REF!
B29: =('QUADRO II'!#REF!) -> #REF! | C29: =('QUADRO II'!#REF!) -> #REF! | D29: ='QUADRO III'!L32*0.0161290322580645 -> #VALUE! | E29: =('QUADRO II'!#REF!) -> #REF! | L29: =ROUND(G29*$K$76,2) -> 0 | M29: =('QUADRO II'!#REF!) -> #REF! | O29: =SUM(M29-N29) -> #REF!
B30: =('QUADRO II'!#REF!) -> #REF! | C30: =('QUADRO II'!#REF!) -> #REF! | D30: ='QUADRO III'!L32*0.0161290322580645 -> #VALUE! | E30: =('QUADRO II'!#REF!) -> #REF! | L30: =ROUND(G30*$K$76,2) -> 0 | M30: =('QUADRO II'!#REF!) -> #REF! | O30: =SUM(M30-N30) -> #REF!
B31: =('QUADRO II'!#REF!) -> #REF! | C31: =('QUADRO II'!#REF!) -> #REF! | D31: ='QUADRO III'!L32*0.0161290322580645 -> #VALUE! | E31: =('QUADRO II'!#REF!) -> #REF! | L31: =ROUND(G31*$K$76,2) -> 0 | M31: =('QUADRO II'!#REF!) -> #REF! | O31: =SUM(M31-N31) -> #REF!
B32: =('QUADRO II'!#REF!) -> #REF! | C32: =('QUADRO II'!#REF!) -> #REF! | D32: ='QUADRO III'!L32*0.0161290322580645 -> #VALUE! | E32: =('QUADRO II'!#REF!) -> #REF! | L32: =ROUND(G32*$K$76,2) -> 0 | M32: =('QUADRO II'!#REF!) -> #REF! | O32: =SUM(M32-N32) -> #REF!
B33: =('QUADRO II'!#REF!) -> #REF! | C33: =('QUADRO II'!#REF!) -> #REF! | D33: ='QUADRO III'!L32*0.0161290322580645 -> #VALUE! | E33: =('QUADRO II'!#REF!) -> #REF! | L33: =ROUND(G33*$K$76,2) -> 0 | M33: =('QUADRO II'!#REF!) -> #REF! | O33: =SUM(M33-N33) -> #REF!
B34: =('QUADRO II'!#REF!) -> #REF! | C34: =('QUADRO II'!#REF!) -> #REF! | D34: ='QUADRO III'!L32*0.0161290322580645 -> #VALUE! | E34: =('QUADRO II'!#REF!) -> #REF! | L34: =ROUND(G34*$K$76,2) -> 0 | M34: =('QUADRO II'!#REF!) -> #REF! | O34: =SUM(M34-N34) -> #REF!
B35: =('QUADRO II'!#REF!) -> #REF! | C35: =('QUADRO II'!#REF!) -> #REF! | D35: ='QUADRO III'!L32*0.0161290322580645 -> #VALUE! | E35: =('QUADRO II'!#REF!) -> #REF! | L35: =ROUND(G35*$K$76,2) -> 0 | M35: =('QUADRO II'!#REF!) -> #REF! | O35: =SUM(M35-N35) -> #REF!
B36: =('QUADRO II'!#REF!) -> #REF! | C36: =('QUADRO II'!#REF!) -> #REF! | D36: ='QUADRO III'!L32*0.0161290322580645 -> #VALUE! | E36: =('QUADRO II'!#REF!) -> #REF! | L36: =ROUND(G36*$K$76,2) -> 0 | M36: =('QUADRO II'!#REF!) -> #REF! | O36: =SUM(M36-N36) -> #REF!
B37: =('QUADRO II'!#REF!) -> #REF! | C37: =('QUADRO II'!#REF!) -> #REF! | D37: ='QUADRO III'!L32*0.0161290322580645 -> #VALUE! | E37: =('QUADRO II'!#REF!) -> #REF! | L37: =ROUND(G37*$K$76,2) -> 0 | M37: =('QUADRO II'!#REF!) -> #REF! | O37: =SUM(M37-N37) -> #REF!
B38: =('QUADRO II'!#REF!) -> #REF! | C38: =('QUADRO II'!#REF!) -> #REF! | D38: ='QUADRO III'!L32*0.0161290322580645 -> #VALUE! | E38: =('QUADRO II'!#REF!) -> #REF! | L38: =ROUND(G38*$K$76,2) -> 0 | M38: =('QUADRO II'!#REF!) -> #REF! | O38: =SUM(M38-N38) -> #REF!
B39: =('QUADRO II'!#REF!) -> #REF! | C39: =('QUADRO II'!#REF!) -> #REF! | D39: ='QUADRO III'!L32*0.0161290322580645 -> #VALUE! | E39: =('QUADRO II'!#REF!) -> #REF! | L39: =ROUND(G39*$K$76,2) -> 0 | M39: =('QUADRO II'!#REF!) -> #REF! | O39: =SUM(M39-N39) -> #REF!
B40: =('QUADRO II'!#REF!) -> #REF! | C40: =('QUADRO II'!#REF!) -> #REF! | D40: ='QUADRO III'!L32*0.0161290322580645 -> #VALUE! | E40: =('QUADRO II'!#REF!) -> #REF! | L40: =ROUND(G40*$K$76,2) -> 0 | M40: =('QUADRO II'!#REF!) -> #REF! | O40: =SUM(M40-N40) -> #REF!
...

Sheet QUADRO IV B
B2: INFORMAÇÕES PARA ARQUIVO NO REGISTRO DE IMÓVEIS
B3: (Lei 4.591 - 16/12/64 - Art. 32 e ABNT NBR 12721)
B4: QUADRO IV B - Resumo das áreas reais para os atos de registro e escrituração - Colunas A a G | I4: Folha No | J4: =('QUADRO IV A'!N3)+1 -> 6
B5: LOCAL DO IMÓVEL: | C5: =('QUADRO I'!$D$5) -> {RUA}, {COMPLEMENTO}; {SETOR} - {CIDADE} | I5: Adotar numeração seguida
I6: Total de folhas: | J6: =('QUADRO I'!$R$6) -> 10
B7: INCORPORADOR | G7: Profissional Responsável:
B8: Nome: | C8: =('QUADRO I'!$C$8) -> {IMCORPORADOR} | G8: Nome: | H8: =('QUADRO I'!$N$8) -> {RESPONSÁVEL TÉCNICO}
B9: Assinatura: | G9: Assinatura:
B10: Data: | C10: =('QUADRO I'!$C$10) -> {DATA HOJE} | G10: Data: | H10: =('QUADRO I'!$C$10) -> {DATA HOJE} | I10: =('QUADRO I'!$Q$10) -> Registro no CREA: | J10: =('QUADRO I'!$S$10) -> {CREA}
C11: ÁREAS REAIS | I11: QUANTIDADE (número de unidades idênticas) | J11: OBSERVAÇÕES
B12: Designação da unidade (19) | C12: ÁREA PRIVATIVA (PRINCIPAL) | D12: OUTRAS ÁREAS PRIVATIVAS (acessórias) | E12: ÁREA PRIVATIVA TOTAL (23) = (B + C) | F12: ÁREA DE USO COMUM (28 + 35) | G12: ÁREA REAL TOTAL (37) = (D + E) | H12: COEFICIENTE DE PROPORCIONALIDA-DE (31)
B13: A | C13: B | D13: C | E13: D | F13: E | G13: F | H13: G
B14: =('QUADRO II'!B17) -> CASA 01 | C14: =CAPA!D9 -> ({ÁREA CONSTRUÍDA PRIVATIVA}+{ÁREA CONSTRUÍDA COMUM}) | D14: ='QUADRO II'!D17 -> ({ÁREA DESCOBERTA PRIVATIVA}+{ÁREA DESCOBERTA COMUM}) | E14: ='QUADRO II'!F17 -> #VALUE! | F14: =('QUADRO II'!K17)+('QUADRO II'!R17) -> #DIV/0! | G14: =SUM(E14+F14) -> #VALUE! | H14: =('QUADRO II'!N17) -> #DIV/0! | I14: =('QUADRO II'!V17) -> 1
B15: =('QUADRO II'!#REF!) -> #REF! | C15: =CAPA!#REF! -> #REF! | D15: ='QUADRO II'!#REF! -> #REF! | E15: ='QUADRO II'!#REF! -> #REF! | F15: =('QUADRO II'!#REF!)+('QUADRO II'!#REF!) -> #REF! | G15: =SUM(E15+F15) -> #REF! | H15: =('QUADRO II'!#REF!) -> #REF! | I15: =('QUADRO II'!#REF!) -> #REF!
B16: =('QUADRO II'!#REF!) -> #REF! | C16: =CAPA!#REF! -> #REF! | D16: ='QUADRO II'!#REF! -> #REF! | E16: ='QUADRO II'!#REF! -> #REF! | F16: =('QUADRO II'!#REF!)+('QUADRO II'!#REF!) -> #REF! | G16: =SUM(E16+F16) -> #REF! | H16: =('QUADRO II'!#REF!) -> #REF! | I16: =('QUADRO II'!#REF!) -> #REF!
B17: =('QUADRO II'!#REF!) -> #REF! | C17: =CAPA!#REF! -> #REF! | D17: ='QUADRO II'!#REF! -> #REF! | E17: ='QUADRO II'!#REF! -> #REF! | F17: =('QUADRO II'!#REF!)+('QUADRO II'!#REF!) -> #REF! | G17: =SUM(E17+F17) -> #REF! | H17: =('QUADRO II'!#REF!) -> #REF! | I17: =('QUADRO II'!#REF!) -> #REF!
B18: =('QUADRO II'!#REF!) -> #REF! | C18: =CAPA!#REF! -> #REF! | D18: ='QUADRO II'!#REF! -> #REF! | E18: ='QUADRO II'!#REF! -> #REF! | F18: =('QUADRO II'!#REF!)+('QUADRO II'!#REF!) -> #REF! | G18: =SUM(E18+F18) -> #REF! | H18: =('QUADRO II'!#REF!) -> #REF! | I18: =('QUADRO II'!#REF!) -> #REF!
B19: =('QUADRO II'!#REF!) -> #REF! | C19: =CAPA!#REF! -> #REF! | D19: ='QUADRO II'!#REF! -> #REF! | E19: ='QUADRO II'!#REF! -> #REF! | F19: =('QUADRO II'!#REF!)+('QUADRO II'!#REF!) -> #REF! | G19: =SUM(E19+F19) -> #REF! | H19: =('QUADRO II'!#REF!) -> #REF! | I19: =('QUADRO II'!#REF!) -> #REF!
B20: =('QUADRO II'!#REF!) -> #REF! | C20: =CAPA!#REF! -> #REF! | D20: ='QUADRO II'!#REF! -> #REF! | E20: ='QUADRO II'!#REF! -> #REF! | F20: =('QUADRO II'!#REF!)+('QUADRO II'!#REF!) -> #REF! | G20: =SUM(E20+F20) -> #REF! | H20: =('QUADRO II'!#REF!) -> #REF! | I20: =('QUADRO II'!#REF!) -> #REF!
B21: =('QUADRO II'!#REF!) -> #REF! | C21: =CAPA!#REF! -> #REF! | D21: ='QUADRO II'!#REF! -> #REF! | E21: ='QUADRO II'!#REF! -> #REF! | F21: =('QUADRO II'!#REF!)+('QUADRO II'!#REF!) -> #REF! | G21: =SUM(E21+F21) -> #REF! | H21: =('QUADRO II'!#REF!) -> #REF! | I21: =('QUADRO II'!#REF!) -> #REF!
B22: =('QUADRO II'!#REF!) -> #REF! | C22: =CAPA!#REF! -> #REF! | D22: ='QUADRO II'!#REF! -> #REF! | E22: ='QUADRO II'!#REF! -> #REF! | F22: =('QUADRO II'!#REF!)+('QUADRO II'!#REF!) -> #REF! | G22: =SUM(E22+F22) -> #REF! | H22: =('QUADRO II'!#REF!) -> #REF! | I22: =('QUADRO II'!#REF!) -> #REF!
B23: =('QUADRO II'!#REF!) -> #REF! | C23: =CAPA!#REF! -> #REF! | D23: ='QUADRO II'!#REF! -> #REF! | E23: ='QUADRO II'!#REF! -> #REF! | F23: =('QUADRO II'!#REF!)+('QUADRO II'!#REF!) -> #REF! | G23: =SUM(E23+F23) -> #REF! | H23: =('QUADRO II'!#REF!) -> #REF! | I23: =('QUADRO II'!#REF!) -> #REF!
B24: =('QUADRO II'!#REF!) -> #REF! | C24: =CAPA!#REF! -> #REF! | D24: ='QUADRO II'!#REF! -> #REF! | E24: ='QUADRO II'!#REF! -> #REF! | F24: =('QUADRO II'!#REF!)+('QUADRO II'!#REF!) -> #REF! | G24: =SUM(E24+F24) -> #REF! | H24: =('QUADRO II'!#REF!) -> #REF! | I24: =('QUADRO II'!#REF!) -> #REF!
B25: =('QUADRO II'!#REF!) -> #REF! | C25: =CAPA!#REF! -> #REF! | D25: ='QUADRO II'!#REF! -> #REF! | E25: ='QUADRO II'!#REF! -> #REF! | F25: =('QUADRO II'!#REF!)+('QUADRO II'!#REF!) -> #REF! | G25: =SUM(E25+F25) -> #REF! | H25: =('QUADRO II'!#REF!) -> #REF! | I25: =('QUADRO II'!#REF!) -> #REF!
B26: =('QUADRO II'!#REF!) -> #REF! | C26: =CAPA!#REF! -> #REF! | D26: ='QUADRO II'!#REF! -> #REF! | E26: ='QUADRO II'!#REF! -> #REF! | F26: =('QUADRO II'!#REF!)+('QUADRO II'!#REF!) -> #REF! | G26: =SUM(E26+F26) -> #REF! | H26: =('QUADRO II'!#REF!) -> #REF! | I26: =('QUADRO II'!#REF!) -> #REF!
... B75: =('QUADRO II'!#REF!) -> #REF! | C75: =CAPA!#REF! -> #REF! | D75: ='QUADRO II'!#REF! -> #REF! | E75: ='QUADRO II'!#REF! -> #REF! | F75: =('QUADRO II'!#REF!)+('QUADRO II'!#REF!) -> #REF! | G75: =SUM(E75+F75) -> #REF! | H75: =('QUADRO II'!#REF!) -> #REF! | I75: =('QUADRO II'!#REF!) -> #REF!
B77: TOTAIS | C77: =SUMPRODUCT(C14:C76,$I14:$I76) -> #REF! | D77: =SUMPRODUCT(D14:D76,$I14:$I76) -> #REF! | E77: =SUMPRODUCT(E14:E76,$I14:$I76) -> #VALUE! | F77: =SUMPRODUCT(F14:F76,$I14:$I76) -> #DIV/0! | G77: =SUMPRODUCT(G14:G76,$I14:$I76) -> #VALUE! | H77: =SUMPRODUCT(H14:H76,$I14:$I76) -> #DIV/0! | I77: =SUM(I14:I76) -> #REF!
B78: Observação 1: | C78: Substituir este quadro pelo quadro IV-B-1 quando for exigida a discriminação de área de terreno de uso exclusivo.
B79: Observação 2: | C79: As áreas das vagas de garagem devem constar:
C80: - na coluna C, quando forem acessórias, conforme definido em 3.7.2.1.2;
C81: - na coluna E, quando forem consideradas como área comum;
C82: - quando forem consideradas unidades autônomas:
C83: - a área principal da vaga será lançada na coluna B;
C84: - a área comum, correspondente à vaga, lançada na coluna E;
C85: - a área total da vaga, soma da área principal com a área comum, lançada na coluna F;
C86: - o respectivo coeficiente de proporcionalidade, lançado na coluna G.

Sheet QUADRO IV B.1
B2: INFORMAÇÕES PARA ARQUIVO NO REGISTRO DE IMÓVEIS
B3: (Lei 4.591 - 16/12/64 - Art. 32 e ABNT NBR 12721)
B4: QUADRO IV B.1 - Resumo das áreas reais para os atos de registro e escrituração - Colunas A a J | K4: Folha No | L4: 6
B5: LOCAL DO IMÓVEL: | D5: =('QUADRO I'!$D$5) -> {RUA}, {COMPLEMENTO}; {SETOR} - {CIDADE} | K5: Adotar numeração seguida
K6: Total de folhas: | L6: =('QUADRO I'!$R$6) -> 10
B7: INCORPORADOR | H7: Profissional Responsável:
B8: Nome: | C8: =('QUADRO I'!$C$8) -> {IMCORPORADOR} | H8: Nome: | I8: =('QUADRO I'!$N$8) -> {RESPONSÁVEL TÉCNICO}
B9: Assinatura: | H9: Assinatura:
B10: Data: | C10: =('QUADRO I'!$C$10) -> {DATA HOJE} | H10: Data: | I10: =('QUADRO I'!$N$10) -> {DATA HOJE} | J10: =('QUADRO I'!$Q$10) -> Registro no CREA: | L10: =('QUADRO I'!$S$10) -> {CREA}
C11: ÁREAS REAIS | H11: ÁREA DE TERRENO | L11: QUANTIDADE (número de unidades idênticas) | M11: OBSERVAÇÕES
B12: Designação da unidade (19) | C12: ÁREA PRIVATIVA (PRINCIPAL) | D12: OUTRAS ÁREAS PRIVATIVAS (acessórias) | E12: ÁREA PRIVATIVA TOTAL (23) = (B + C) | F12: ÁREA DE USO COMUM (28 + 35) | G12: ÁREA REAL TOTAL (37) = (D + E) | H12: ÁREA DE TERRENO DE USO EXCLUSIVO (inclui área do terreno na projeção da edificação) | I12: ÁREA DE TERRENO DE USO COMUM | J12: ÁREA DE TERRENO TOTAL | K12: COEFICIENTE DE PROPORCIONA-LIDADE (31)
B14: A | C14: B | D14: C | E14: D | F14: E | G14: F | H14: G | I14: H | J14: I | K14: J
B15: =('QUADRO II'!B17) -> CASA 01 | C15: =CAPA!D9 -> ({ÁREA CONSTRUÍDA PRIVATIVA}+{ÁREA CONSTRUÍDA COMUM}) | D15: ='QUADRO IV B'!D14 -> ({ÁREA DESCOBERTA PRIVATIVA}+{ÁREA DESCOBERTA COMUM}) | E15: =SUM(C15+D15) -> #VALUE! | F15: =('QUADRO II'!K17)+('QUADRO II'!R17) -> #DIV/0! | G15: =SUM(E15+F15) -> #VALUE! | H15: =G15 -> #VALUE! | J15: =SUM(H15+I15) -> #VALUE! | K15: =('QUADRO II'!N17) -> #DIV/0! | L15: =('QUADRO II'!V17) -> 1
B16: =('QUADRO II'!#REF!) -> #REF! | C16: =CAPA!#REF! -> #REF! | D16: ='QUADRO IV B'!D15 -> #REF! | E16: =SUM(C16+D16) -> #REF! | F16: =('QUADRO II'!#REF!)+('QUADRO II'!#REF!) -> #REF! | G16: =SUM(E16+F16) -> #REF! | H16: =G16 -> #REF! | J16: =SUM(H16+I16) -> #REF! | K16: =('QUADRO II'!#REF!) -> #REF! | L16: =('QUADRO II'!#REF!) -> #REF!
B17: =('QUADRO II'!#REF!) -> #REF! | C17: =CAPA!#REF! -> #REF! | D17: ='QUADRO IV B'!D16 -> #REF! | E17: =SUM(C17+D17) -> #REF! | F17: =('QUADRO II'!#REF!)+('QUADRO II'!#REF!) -> #REF! | G17: =SUM(E17+F17) -> #REF! | H17: =G17 -> #REF! | J17: =SUM(H17+I17) -> #REF! | K17: =('QUADRO II'!#REF!) -> #REF! | L17: =('QUADRO II'!#REF!) -> #REF!
B18: =('QUADRO II'!#REF!) -> #REF! | C18: =CAPA!#REF! -> #REF! | D18: ='QUADRO IV B'!D17 -> #REF! | E18: =SUM(C18+D18) -> #REF! | F18: =('QUADRO II'!#REF!)+('QUADRO II'!#REF!) -> #REF! | G18: =SUM(E18+F18) -> #REF! | H18: =G18 -> #REF! | J18: =SUM(H18+I18) -> #REF! | K18: =('QUADRO II'!#REF!) -> #REF! | L18: =('QUADRO II'!#REF!) -> #REF!
B19: =('QUADRO II'!#REF!) -> #REF! | C19: =CAPA!#REF! -> #REF! | D19: ='QUADRO IV B'!D18 -> #REF! | E19: =SUM(C19+D19) -> #REF! | F19: =('QUADRO II'!#REF!)+('QUADRO II'!#REF!) -> #REF! | G19: =SUM(E19+F19) -> #REF! | H19: =G19 -> #REF! | J19: =SUM(H19+I19) -> #REF! | K19: =('QUADRO II'!#REF!) -> #REF! | L19: =('QUADRO II'!#REF!) -> #REF!
B20: =('QUADRO II'!#REF!) -> #REF! | C20: =CAPA!#REF! -> #REF! | D20: ='QUADRO IV B'!D19 -> #REF! | E20: =SUM(C20+D20) -> #REF! | F20: =('QUADRO II'!#REF!)+('QUADRO II'!#REF!) -> #REF! | G20: =SUM(E20+F20) -> #REF! | H20: =G20 -> #REF! | J20: =SUM(H20+I20) -> #REF! | K20: =('QUADRO II'!#REF!) -> #REF! | L20: =('QUADRO II'!#REF!) -> #REF!
B21: =('QUADRO II'!#REF!) -> #REF! | C21: =CAPA!#REF! -> #REF! | D21: ='QUADRO IV B'!D20 -> #REF! | E21: =SUM(C21+D21) -> #REF! | F21: =('QUADRO II'!#REF!)+('QUADRO II'!#REF!) -> #REF! | G21: =SUM(E21+F21) -> #REF! | H21: =G21 -> #REF! | J21: =SUM(H21+I21) -> #REF! | K21: =('QUADRO II'!#REF!) -> #REF! | L21: =('QUADRO II'!#REF!) -> #REF!
B22: =('QUADRO II'!#REF!) -> #REF! | C22: =CAPA!#REF! -> #REF! | D22: ='QUADRO IV B'!D21 -> #REF! | E22: =SUM(C22+D22) -> #REF! | F22: =('QUADRO II'!#REF!)+('QUADRO II'!#REF!) -> #REF! | G22: =SUM(E22+F22) -> #REF! | H22: =G22 -> #REF! | J22: =SUM(H22+I22) -> #REF! | K22: =('QUADRO II'!#REF!) -> #REF! | L22: =('QUADRO II'!#REF!) -> #REF!
B23: =('QUADRO II'!#REF!) -> #REF! | C23: =CAPA!#REF! -> #REF! | D23: ='QUADRO IV B'!D22 -> #REF! | E23: =SUM(C23+D23) -> #REF! | F23: =('QUADRO II'!#REF!)+('QUADRO II'!#REF!) -> #REF! | G23: =SUM(E23+F23) -> #REF! | H23: =G23 -> #REF! | J23: =SUM(H23+I23) -> #REF! | K23: =('QUADRO II'!#REF!) -> #REF! | L23: =('QUADRO II'!#REF!) -> #REF!
B24: =('QUADRO II'!#REF!) -> #REF! | C24: =CAPA!#REF! -> #REF! | D24: ='QUADRO IV B'!D23 -> #REF! | E24: =SUM(C24+D24) -> #REF! | F24: =('QUADRO II'!#REF!)+('QUADRO II'!#REF!) -> #REF! | G24: =SUM(E24+F24) -> #REF! | H24: =G24 -> #REF! | J24: =SUM(H24+I24) -> #REF! | K24: =('QUADRO II'!#REF!) -> #REF! | L24: =('QUADRO II'!#REF!) -> #REF!
B25: =('QUADRO II'!#REF!) -> #REF! | C25: =CAPA!#REF! -> #REF! | D25: ='QUADRO IV B'!D24 -> #REF! | E25: =SUM(C25+D25) -> #REF! | F25: =('QUADRO II'!#REF!)+('QUADRO II'!#REF!) -> #REF! | G25: =SUM(E25+F25) -> #REF! | H25: =G25 -> #REF! | J25: =SUM(H25+I25) -> #REF! | K25: =('QUADRO II'!#REF!) -> #REF! | L25: =('QUADRO II'!#REF!) -> #REF!
B26: =('QUADRO II'!#REF!) -> #REF! | C26: =CAPA!#REF! -> #REF! | D26: ='QUADRO IV B'!D25 -> #REF! | E26: =SUM(C26+D26) -> #REF! | F26: =('QUADRO II'!#REF!)+('QUADRO II'!#REF!) -> #REF! | G26: =SUM(E26+F26) -> #REF! | H26: =G26 -> #REF! | J26: =SUM(H26+I26) -> #REF! | K26: =('QUADRO II'!#REF!) -> #REF! | L26: =('QUADRO II'!#REF!) -> #REF!
B27: =('QUADRO II'!#REF!) -> #REF! | C27: =CAPA!#REF! -> #REF! | D27: ='QUADRO IV B'!D26 -> #REF! | E27: =SUM(C27+D27) -> #REF! | F27: =('QUADRO II'!#REF!)+('QUADRO II'!#REF!) -> #REF! | G27: =SUM(E27+F27) -> #REF! | H27: =G27 -> #REF! | J27: =SUM(H27+I27) -> #REF! | K27: =('QUADRO II'!#REF!) -> #REF! | L27: =('QUADRO II'!#REF!) -> #REF!
... B76: =('QUADRO II'!#REF!) -> #REF! | C76: =CAPA!#REF! -> #REF! | D76: ='QUADRO IV B'!D75 -> #REF! | E76: =SUM(C76+D76) -> #REF! | F76: =('QUADRO II'!#REF!)+('QUADRO II'!#REF!) -> #REF! | G76: =SUM(E76+F76) -> #REF! | H76: =G76 -> #REF! | J76: =SUM(H76+I76) -> #REF! | K76: =('QUADRO II'!#REF!) -> #REF! | L76: =('QUADRO II'!#REF!) -> #REF!
B78: TOTAIS | C78: =SUMPRODUCT(C15:C77,$L15:$L77) -> #REF! | D78: =SUMPRODUCT(D15:D77,$L15:$L77) -> #REF! | E78: =SUMPRODUCT(E15:E77,$L15:$L77) -> #VALUE! | F78: =SUMPRODUCT(F15:F77,$L15:$L77) -> #DIV/0! | G78: =SUMPRODUCT(G15:G77,$L15:$L77) -> #VALUE! | H78: =SUMPRODUCT(H15:H77,$L15:$L77) -> #VALUE! | I78: =SUMPRODUCT(I15:I77,$L15:$L77) -> #REF! | J78: =SUMPRODUCT(J15:J77,$L15:$L77) -> #VALUE! | K78: =SUMPRODUCT(K15:K77,$L15:$L77) -> #DIV/0! | L78: =SUM(L15:L77) -> #REF!
B79: Observação: | C79: Este quadro deverá substituir o quadro QIV-B, quando for exigida a discriminação de área de terreno de uso exclusivo.
C80: Quando não for o caso, deverá ser omitido na apresentação do conjunto de planilhas.

Sheet QUADRO V
B2: INFORMAÇÕES PARA ARQUIVO NO REGISTRO DE IMÓVEIS
B3: (Lei 4.591 - 16/12/64 - Art. 32 e ABNT NBR 12721)
B4: QUADRO V - INFORMAÇÕES GERAIS | J4: Adotar numeração seguida do quadro I ao VIII
B5: Local do imóvel | D5: =('QUADRO I'!$D$5) -> {RUA}, {COMPLEMENTO}; {SETOR} - {CIDADE} | J5: Total de folhas: | K5: 10
J6: Folha No | K6: 7
B7: INCORPORADOR | H7: Profissional Responsável:
B8: Nome: | C8: =('QUADRO I'!$C$8) -> {IMCORPORADOR} | H8: Nome: | I8: =('QUADRO I'!$N$8) -> {RESPONSÁVEL TÉCNICO}
B9: Assinatura: | H9: Assinatura:
B10: Data: | C10: =('QUADRO I'!$C$10) -> {DATA HOJE} | H10: Data: | I10: =('QUADRO I'!$N$10) -> {DATA HOJE} | J10: =('QUADRO I'!$Q$10) -> Registro no CREA: | L10: =('QUADRO I'!$S$10) -> {CREA}
B12: a) Tipo de Empreendimento:
B13: Condomínio Residencial composto por habitação seriada;
B15: b) Incorporador:
B16: ='QUADRO I'!C8 -> {IMCORPORADOR}
B18: c) Proprietário do Terreno:
B19: ='QUADRO I'!C8 -> {IMCORPORADOR}
B21: d) Autores dos Projetos:
B22: ='QUADRO I'!N8 -> {RESPONSÁVEL TÉCNICO} | E22: ='QUADRO I'!S10 -> {CREA}
B24: e) Descrição do Empreendimento:
B25: O empreendimento consiste de 01 (um) terreno de 15.981,3 1M², dividido em 62 (sessenta e duas) frações ideais referente as casas C-1 a C-62
B27: A fração ideal 1 a 6 com área | D27: ='QUADRO II'!F17 -> #VALUE! | E27: m², corresponde a | F27: =CAPA!H9 -> #DIV/0! | G27: da área total.
B28: A fração ideal 7 a 30 com área | D28: ='QUADRO II'!#REF! -> #REF! | E28: m², corresponde a | F28: =CAPA!#REF! -> #REF! | G28: da área total.
B29: A fração ideal 31 a 39 com área | D29: ='QUADRO II'!#REF! -> #REF! | E29: m², corresponde a | F29: =CAPA!#REF! -> #REF! | G29: da área total.
B30: A fração ideal 40 a 51 com área | D30: ='QUADRO II'!#REF! -> #REF! | E30: m², corresponde a | F30: =CAPA!#REF! -> #REF! | G30: da área total.
B31: A fração ideal 52 a 61 com área | D31: ='QUADRO II'!#REF! -> #REF! | E31: m², corresponde a | F31: =CAPA!#REF! -> #REF! | G31: da área total.
B32: A fração ideal 62 com área | D32: ='QUADRO II'!#REF! -> #REF! | E32: m², corresponde a | F32: =CAPA!#REF! -> #REF! | G32: da área total.
B34: f) Descrição das residências seriadas:
B36: CASAS 01 A 62 - CONFORME MEMORIAL DE INSTITUIÇÃO DE CONDOMÍNIO E CERTIDÃO DE LANÇAMENTO.

Sheet QUADRO VI
B2: INFORMAÇÕES PARA ARQUIVO NO REGISTRO DE IMÓVEIS
B3: (Lei 4.591 - 16/12/64 - Art. 32 e ABNT NBR 12721)
B4: QUADRO VI - Memorial Descritivo dos Equipamentos | J4: Folha No | K4: =('QUADRO V'!K6)+1 -> 8
B5: Local do imóvel: | D5: =('QUADRO I'!$D$5) -> {RUA}, {COMPLEMENTO}; {SETOR} - {CIDADE} | J5: Adotar numeração seguida do quadro I ao VIII
J6: Total de folhas: | K6: =('QUADRO I'!$R$6) -> 10
B7: INCORPORADOR | H7: Profissional Responsável:
B8: Nome: | C8: =('QUADRO I'!$C$8) -> {IMCORPORADOR} | H8: Nome: | I8: =('QUADRO I'!$N$8) -> {RESPONSÁVEL TÉCNICO}
B9: Assinatura: | H9: Assinatura:
B10: Data: | C10: =('QUADRO I'!$C$10) -> {DATA HOJE} | H10: Data: | I10: =('QUADRO I'!$N$10) -> {DATA HOJE} | J10: =('QUADRO I'!$Q$10) -> Registro no CREA: | L10: =('QUADRO I'!$S$10) -> {CREA}
B12: EQUIPAMENTOS | D12: TIPO (OU MARCA) | F12: ACABAMENTO | H12: DETALHES GERAIS
B13: Instalações elétricas | D13: Linha popular | F13: Montagens e Instalações acabadas | H13: Conforme projetos anotados no CREA-GO
B14: Aparelho sanitário | D14: Linha popular | F14: Louça branca
B15: Instalações hidráulicas | D15: Linha popular | F15: Montagens e Instalações acabadas
B16: Telhas | D16: Fibrocimento / cerâmica | F16: Ondulada / americana
B17: Portas e portais | D17: Madeira Laminada | F17: Verniz
B18: Vidro | D18: Blindex | F18: Blindex
B19: Metais | D19: Linha popular | F19: Cromado/ PVC
B20: Janelas | D20: aluminio | F20: Eletrostatica

Sheet QUADRO VII
B2: INFORMAÇÕES PARA ARQUIVO NO REGISTRO DE IMÓVEIS
B3: (Lei 4.591 - 16/12/64 - Art. 32 e ABNT NBR 12721)
B4: QUADRO VII - MEMORIAL DESCRITIVO DOS ACABAMENTOS (Dependências de uso privativo) | J4: Folha No | K4: =('QUADRO VI'!K4)+1 -> 9
B5: Local do imóvel: | D5: =('QUADRO I'!$D$5) -> {RUA}, {COMPLEMENTO}; {SETOR} - {CIDADE} | J5: Adotar numeração seguida do quadro I ao VIII
J6: Total de folhas: | K6: =('QUADRO I'!$R$6) -> 10
B7: INCORPORADOR | H7: Profissional Responsável:
B8: Nome: | C8: =('QUADRO I'!$C$8) -> {IMCORPORADOR} | H8: Nome: | I8: =('QUADRO I'!$N$8) -> {RESPONSÁVEL TÉCNICO}
B9: Assinatura: | H9: Assinatura:
B10: Data: | C10: =('QUADRO I'!$C$10) -> {DATA HOJE} | H10: Data: | I10: =('QUADRO I'!$N$10) -> {DATA HOJE} | J10: =('QUADRO I'!$Q$10) -> Registro no CREA: | L10: =('QUADRO I'!$S$10) -> {CREA}
B12: DEPENDÊNCIAS | D12: PISOS | G12: PAREDES | J12: TETOS | L12: OUTROS
B13: Sala de estar e circulação | D13: Cerâmica | G13: Massa única | J13: Laje
B14: Quartos | D14: Cerâmica | G14: Massa única | J14: Laje
B15: Banheiro | D15: Cerâmica | G15: cerâmica | J15: Laje
B16: Cozinha | D16: Cerâmica | G16: cerâmica | J16: Laje
B17: Garagem | D17: Cerâmica | G17: Textura | J17: Laje
B18: Área de Serviço | D18: Cerâmica | G18: cerâmica | J18: Laje

Sheet QUADRO VIII
B2: INFORMAÇÕES PARA ARQUIVO NO REGISTRO DE IMÓVEIS
B3: (Lei 4.591 - 16/12/64 - Art. 32 e ABNT NBR 12721)
B4: QUADRO VIII - MEMORIAL DESCRITIVO DOS ACABAMENTOS (Dependências de uso comum) | J4: Folha No
B5: Local do imóvel: | D5: ='QUADRO I'!D5:O6 -> {RUA}, {COMPLEMENTO}; {SETOR} - {CIDADE} | J5: Adotar numeração seguida do quadro I ao VIII
J6: Total de folhas: | K6: 10
B7: INCORPORADOR | H7: Profissional Responsável:
B8: Nome: | C8: ='QUADRO VII'!C8 -> {IMCORPORADOR} | H8: Nome: | I8: =('QUADRO I'!$N$8) -> {RESPONSÁVEL TÉCNICO}
B9: Assinatura: | H9: Assinatura:
B10: Data: | C10: ='QUADRO VII'!C10 -> {DATA HOJE} | H10: Data: | I10: =('QUADRO I'!$N$10) -> {DATA HOJE} | J10: =('QUADRO I'!$Q$10) -> Registro no CREA: | L10: =('QUADRO I'!$S$10) -> {CREA}
B11: DEPENDÊNCIAS | D11: PISOS | G11: PAREDES | J11: TETOS | L11: OUTROS
B12: ÁREA DE FESTAS 01 | D12: CERÂMICA | G12: TEXTURA | J12: LAJE
B13: ÁREA DE FESTAS 02 | D13: CERÂMICA | G13: TEXTURA | J13: LAJE
B14: WC MASCULINO | D14: CERÂMICA | G14: CERÂMICA | J14: LAJE
B15: WC FEMININO | D15: CERÂMICA | G15: CERÂMICA | J15: LAJE
B16: GUARITA | D16: CERÂMICA | G16: TEXTURA | J16: LAJE
B17: WC GUARITA | D17: CERÂMICA | G17: CERÂMICA | J17: LAJE
B18: LIXEIRAS | D18: CONCRETO | G18: CERÂMICA | J18: LAJE
